Workbook

Sheet ZONAL SUMMARY  (3)
A1: MINISTRY OF EDUCATION SCIENCE AND TECHNOLOGY
A2: DEPARTMENT OF SECONDARY
A3: SITUATION REPORT OF SECONDARY SCHOOL BY ZONES
A5: S/N | B5: NAME OF ZONE | D5: TOTAL NO OF LEARNERS IN SECONDARY SCHOOLS | E5: TOTAL NO OF LEARNERS IN TECHNICAL COLLEGES | F5: NUMBER OF TEACHERS | G5: NUMBER OF PRINCIPALS | H5: NUMBER OF SCHOOLS | I5: TOTAL NUMBER OF SCHOOLS | J5: TOTAL AMOUNT DUE @₦150 PER LEARNER IN SECONDARY SCHOOLS | K5: TOTAL AMOUNT DUE @₦1200 PER LEARNER IN TECHNICAL COLLEGES | L5: TOTAL NUMBER OF SCHOOLS WITH < OR = 1000 LEARNERS | M5: TOTAL NUMBER OF SCHOOLS WITH > 1000 LEARNERS
A6: 1 | B6: Abeokuta North | D6: ='ABEOKUTA NORTH'!CM33 -> 27701 | E6: NIL | I6: ='ABEOKUTA NORTH NEW'!B42 -> 27 | J6: ='ABEOKUTA NORTH NEW'!#REF! -> #REF! | K6: ='ABEOKUTA NORTH NEW'!#REF! -> #REF! | L6: ='ABEOKUTA NORTH NEW'!#REF! -> #REF! | M6: ='ABEOKUTA NORTH NEW'!#REF! -> #REF!
A7: 2 | B7: Abeokuta South | D7: ='ABEOKUTA SOUTH'!CP47-E7 -> 0 | E7: ='ABEOKUTA SOUTH'!CP46 -> 0 | I7: ='ABEOKUTA SOUTH NEW'!B49 -> 40 | J7: ='ABEOKUTA SOUTH NEW'!C49 -> #REF! | K7: ='ABEOKUTA SOUTH NEW'!#REF! -> #REF! | L7: ='ABEOKUTA SOUTH NEW'!C49 -> #REF! | M7: ='ABEOKUTA SOUTH NEW'!#REF! -> #REF!
A8: 3 | B8: Ado-Odo/Ota | D8: =#REF!-E8 -> #REF! | E8: =#REF! -> #REF! | I8: ='ADO ODO JUNIOR'!A27+'ADO ODO SENIOR'!A27+'ADO ODO COMBINED'!A26 -> 53
A9: 4 | B9: Ewekoro | D9: =EWEKORO!CM20-E9 -> 13111 | E9: =EWEKORO!CM19 -> 233 | I9: ='EWEKORO NEW'!B22 -> 14 | J9: ='EWEKORO NEW'!C22 -> 9 | K9: ='EWEKORO NEW'!D22 -> 5 | L9: ='EWEKORO NEW'!C22 -> 9 | M9: ='EWEKORO NEW'!D22 -> 5
A10: 5 | B10: Ifo | D10: =Ifo!#REF! -> #REF! | E10: NIL | I10: ='Ifo new'!A43 -> 31 | J10: ='Ifo new'!B43 -> #REF! | K10: ='Ifo new'!C43 -> #REF! | L10: ='Ifo new'!B43 -> #REF! | M10: ='Ifo new'!#REF! -> #REF!
A11: 6 | B11: Ijebu East | D11: ='Ijebu East'!CM25 -> 0 | E11: NIL | I11: ='Ijebu East New'!A29 -> 19 | J11: ='Ijebu East New'!B29 -> 0 | K11: ='Ijebu East New'!#REF! -> #REF! | L11: ='Ijebu East New'!B29 -> 0 | M11: ='Ijebu East New'!#REF! -> #REF!
A12: 7 | B12: Ijebu North East | D12: ='Ijebu North EAST'!CV20 -> 4175 | E12: NIL | I12: ='Ijebu North East New'!A20 -> 14 | J12: ='Ijebu North East New'!B20 -> 0 | K12: ='Ijebu North East New'!#REF! -> #REF! | L12: ='Ijebu North East New'!B20 -> 0 | M12: ='Ijebu North East New'!#REF! -> #REF!
A13: 8 | B13: Ijebu North | D13: ='Ijebu North'!CD44-E13 -> 16768 | E13: ='Ijebu North'!CD27 -> 106 | I13: ='Ijebu North New'!A49 -> 36 | J13: ='Ijebu North New'!B49 -> 0 | K13: ='Ijebu North New'!#REF! -> #REF! | L13: ='Ijebu North New'!B49 -> 0 | M13: ='Ijebu North New'!#REF! -> #REF!
A14: 9 | B14: Ijebu Ode | D14: ='Ijebu Ode'!CM33-E14 -> 25755 | E14: ='Ijebu Ode'!CM30 -> 489 | I14: ='Ijebu Ode New'!A34 -> 26 | J14: ='Ijebu Ode New'!B49 -> 0 | K14: ='Ijebu Ode New'!#REF! -> #REF! | L14: ='Ijebu Ode New'!B34 -> 0 | M14: ='Ijebu Ode New'!#REF! -> #REF!
A15: 10 | B15: Ikenne | D15: =Ikenne!CM24 -> 0 | E15: NIL | I15: ='Ikenne new'!B27 -> 18 | J15: ='Ikenne new'!C27 -> 0 | K15: ='Ikenne new'!#REF! -> #REF! | L15: ='Ikenne new'!C27 -> 0 | M15: ='Ikenne new'!#REF! -> #REF!
A16: 11 | B16: Imeko/Afon | D16: ='Imeko Afon'!CN55 -> 6371 | E16: NIL | I16: ='Imeko Afon NEW'!B35 -> 19 | J16: ='Imeko Afon NEW'!#REF! -> #REF! | K16: ='Imeko Afon NEW'!#REF! -> #REF! | L16: ='Imeko Afon NEW'!#REF! -> #REF! | M16: ='Imeko Afon NEW'!#REF! -> #REF!
A17: 12 | B17: Ipokia | D17: =IPOKIA!CM30 -> 17807 | E17: NIL | I17: ='Ipokia New'!A33 -> 24 | J17: ='Ipokia New'!B33 -> 0 | K17: ='Ipokia New'!#REF! -> #REF! | L17: ='Ipokia New'!B33 -> 0 | M17: ='Ipokia New'!#REF! -> #REF!
A18: 13 | B18: Obafemi Owode | D18: ='Obafemi Owode'!CX29 -> 0 | E18: NIL | I18: ='OBAFEMI NEW'!B33 -> 23 | J18: ='OBAFEMI NEW'!#REF! -> #REF! | K18: ='OBAFEMI NEW'!#REF! -> #REF! | L18: ='OBAFEMI NEW'!#REF! -> #REF! | M18: ='OBAFEMI NEW'!#REF! -> #REF!
A19: 14 | B19: Odeda | D19: =Odeda!CJ25 -> 0 | E19: NIL | I19: ='Odeda new'!B24 -> 18 | J19: ='Odeda new'!#REF! -> #REF! | K19: ='Odeda new'!#REF! -> #REF! | L19: ='Odeda new'!#REF! -> #REF! | M19: ='Odeda new'!#REF! -> #REF!
A20: 15 | B20: Odogbolu | D20: =ODOGBOLU!CM32 -> 8515 | E20: NIL | I20: ='ODOGBOLU NEW'!A38 -> 28 | J20: ='ODOGBOLU NEW'!B38 -> 0 | K20: ='ODOGBOLU NEW'!#REF! -> #REF! | L20: ='ODOGBOLU NEW'!B38 -> 0 | M20: ='ODOGBOLU NEW'!#REF! -> #REF!
A21: 16 | B21: Remo North | D21: ='Remo North'!CM16-E21 -> 3485 | E21: ='Remo North'!CM15 -> 28 | I21: ='Remo north new '!B17 -> 9 | J21: ='Remo north new '!#REF! -> #REF! | K21: ='Remo north new '!#REF! -> #REF! | L21: ='Remo north new '!#REF! -> #REF! | M21: ='Remo north new '!#REF! -> #REF!
A22: 17 | B22: Sagamu | D22: =Sagamu!CD35 -> 29003 | E22: NIL | I22: ='Sagamu New'!B38 -> 28 | J22: ='Sagamu New'!#REF! -> #REF! | K22: ='Sagamu New'!#REF! -> #REF! | L22: ='Sagamu New'!#REF! -> #REF! | M22: ='Sagamu New'!#REF! -> #REF!
A23: 18 | B23: Ogun Waterside | D23: ='OGUN WATERSIDE'!CN55 -> 6789 | E23: NIL | I23: ='OGUN WATERSIDE new'!A36 -> 20 | J23: ='OGUN WATERSIDE new'!B36 -> 0 | K23: ='OGUN WATERSIDE new'!#REF! -> #REF! | L23: ='OGUN WATERSIDE new'!B36 -> 0 | M23: ='OGUN WATERSIDE new'!#REF! -> #REF!
A24: 19 | B24: Yewa North | D24: ='YEWA NORTH'!CJ40-E24 -> 15782 | E24: ='YEWA NORTH'!CJ18 -> 437 | I24: ='YEWA NORTH NEW'!B48 -> 35 | J24: ='YEWA NORTH NEW'!#REF! -> #REF! | K24: ='YEWA NORTH NEW'!#REF! -> #REF! | L24: ='YEWA NORTH NEW'!#REF! -> #REF! | M24: ='YEWA NORTH NEW'!#REF! -> #REF!
A25: 20 | B25: Yewa South | D25: ='YEWA SOUTH'!CN51 -> 22911 | E25: NIL | I25: ='Yewa South new'!B41 -> 28 | J25: ='Yewa South new'!C41 -> 0 | K25: ='Yewa South new'!D41 -> 0 | L25: ='Yewa South new'!#REF! -> #REF! | M25: ='Yewa South new'!#REF! -> #REF!
B26: GRAND TOTAL | D26: =SUM(D6:D25) -> #REF! | E26: =SUM(E6:E25) -> #REF! | I26: =SUM(I6:I25) -> 510 | J26: =SUM(J6:J25) -> #REF! | K26: =SUM(K6:K25) -> #REF! | L26: =SUM(L6:L25) -> #REF! | M26: =SUM(M6:M25) -> #REF!
D29: =D26*150 -> #REF! | E29: =D13*150 -> 2515200
E30: =E26*1200 -> #REF!

Sheet ADO ODO JUNIOR
A1: MINISTRY OF EDUCATION, SCIENCE AND TECHNOLOGY, OKE MOSAN, ABEOKUTA,
A2: ZONAL EDUCATION OFFICE, ADO-ODO-OTA,
A3: SITUATION REPORT ON PUBLIC SECONDARY SCHOOLS.
A5: S/NO | B5: NAME OF SCHOOL
A7: 1 | B7: ADO-ODO HIGH SCHOOL (JUNIOR), ADO-ODO
A8: 2 | B8: AGBARA COMMUNITY JUNIOR HIGH SCHOOL, EDU
A9: 3 | B9: AJOGBO GRAMMAR SCHOOL (JUNIOR)
A10: 4 | B10: ALAMUWA GRAMMAR SCHOOL (JUNIOR) ADO ODO
A11: 5 | B11: ANGLICAN GRAMMAR SCHOOL (JUNIOR), OTA
A12: 6 | B12: ANSAR-UD-DEEN. COMPREHENSIVE COLLEGE (JUNIOR) OTA
A13: 7 | B13: ANSAR-UD-DEEN. COMPREHENSIVE HIGH SCHOOL (SENIOR) LAFENWA, OTA.
A14: 8 | B14: COMMUNITY HIGH SCHOOL JUNIOR, ALAPOTI
A15: 9 | B15: COMMUNITY HIGH SCHOOL JUNIOR, IROKO OTA.
A16: 10 | B16: IGANMODE GRAMMAR SCHOOL (JUNIOR) OTA
A17: 11 | B17: IGBESA HIGH SCHOOL(JUNIOR) IGBESA.
A18: 12 | B18: IJU EBIYE HIGH SCHOOL (SENIOR), IJU, OTA
... A24: 18 | B24: UNITY HIGH SCHOOL (JUNIOR) KAJOLA IBOORO
A27: =COUNTA(A7:A24) -> 18

Sheet ADO ODO SENIOR
A1: MINISTRY OF EDUCATION, SCIENCE AND TECHNOLOGY, OKE MOSAN, ABEOKUTA,
A2: ZONAL EDUCATION OFFICE, ADO-ODO-OTA,
A3: SITUATION REPORT ON PUBLIC SECONDARY SCHOOLS.
A5: S/NO | B5: NAME OF SCHOOL
A7: 1 | B7: ADO-ODO HIGH SCHOOL (SENIOR), ADO-ODO
A8: 2 | B8: AGBARA COMMUNITY SENIOR HIGH SCHOOL, EDU
A9: 3 | B9: AJOGBO GRAMMAR SCHOOL (SENIOR)
A10: 4 | B10: ALAMUWA GRAMMAR SCHOOL (SENIOR) ADO ODO
A11: 5 | B11: ANGLICAN GRAMMAR SCHOOL (SENIOR), OTA
A12: 6 | B12: ANSAR-UD-DEEN. COMPREHENSIVE COLLEGE (SENIOR) OTA
A13: 7 | B13: ANSAR-UD-DEEN. COMPREHENSIVE HIGH SCHOOL (SENIOR) LAFENWA, OTA.
A14: 8 | B14: COMMUNITY HIGH SCHOOL SENIOR, ALAPOTI
A15: 9 | B15: COMMUNITY HIGH SCHOOL SNR, IROKO OTA.
A16: 10 | B16: IGANMODE GRAMMAR SCHOOL (SENIOR) OTA
A17: 11 | B17: IGBESA HIGH SCHOOL(SENIOR) IGBESA.
A18: 12 | B18: IJU EBIYE HIGH SCHOOL (SENIOR), IJU, OTA
... A24: 18 | B24: UNITY HIGH SCHOOL (SENIOR) KAJOLA IBOORO
A27: =COUNTA(A7:A24) -> 18

Sheet ADO ODO COMBINED
A1: MINISTRY OF EDUCATION, SCIENCE AND TECHNOLOGY, OKE MOSAN, ABEOKUTA,
A2: ZONAL EDUCATION OFFICE, ADO-ODO-OTA,
A3: SITUATION REPORT ON PUBLIC SECONDARY SCHOOLS.
A5: S/NO | B5: NAME OF SCHOOL
A7: 1 | B7: ADIE OWE COMM HIGH SCHOOL
A8: 2 | B8: AFRICAN CHURCH COMM. H. SCHOOL
A9: 3 | B9: AGBARA GRAMMAR SCHOOL, AGBARA
A10: 4 | B10: ANSAR-UD DEEN COMPRE COLLEGE,ITELE
A11: 5 | B11: ARAROMI COMMUNITY HIGH SCHOOL, ORITA
A12: 6 | B12: COMMUNITY HIGH SCHOOL,IGBALA
A13: 7 | B13: EJILA AWORI COMMUNITY SECONDARY SCHOOL, OTA.
A14: 8 | B14: GOVERNMENT SCIENCE AND TECHNICAL COLLEGE, IGBESA.
A15: 9 | B15: ILOGBO ASOWO COMMUNITY HIGH SCH
A16: 10 | B16: IYESI-OTA HIGH SCHOOL,IYESI -OTA SITUATION REPORT ON PUBLIC SEC. SCHOOLS.
A17: 11 | B17: ST MICHAEL'S HIGH SCHOOL,OTA
A18: 12 | B18: TOYON HIGH SCHOOL, ERE
... A23: 17 | B23: YEMAA COMMUNITY SITUATION REPORT ON PUBLIC SEC. SCHOOLS.
A26: =COUNTA(A7:A23) -> 17

Sheet ABEOKUTA SOUTH NEW
B1: MINISTRY OF EDUCATION, SCIENCE AND TECHNOLOGY, OKE MOSAN, ABEOKUTA
B2: SECONDARY EDUCATION DEPARTMENT
C3: ABEOKUTA SOUTH
C4: JUNIOR SCHOOL
B5: S/N | C5: SCHOOL
B7: 1 | C7: ABEOKUTA GIRLS GRAMMAR SCHOOL, ONIKOLOBO
B8: 2 | C8: ABEOKUTA GRAMMAR SCHOOL, IDI ABA
B9: 3 | C9: ANGLICAN HIGH SCHOOL, QUARRY ROAD, IBARA
B10: 4 | C10: ASERO HIGH SCHOOL, ASERO
B11: 5 | C11: BAPTIST BOYS' HIGH, SAJE
B12: 6 | C12: BAPTIST GIRLS' COLLEGE SCHOOL, IDI ABA
B13: 7 | C13: CATHOLIC COMPREHENSIVVE HIGH SCHOOL, PANSEKE, IBARA
B14: 8 | C14: EGBA COMPREHENSIVE HIGH SCHOOL, ASERO
B15: 9 | C15: IGBORE HIGH SCHOOL, IGBORE
B16: 10 | C16: IJEMO-TITUN HIGH SCHOOL, HOUSING ESTATE, IBARA
B17: 11 | C17: LANTORO HIGH SCHOOL, LANTORO
B18: 12 | C18: LISABI GRAMMAR SCHOOL, IDI ABA
... B25: 19 | C25: SAINT LEO’S COLLEGE, ONIKOKO
C26: SENIOR SCHOOL
B27: 20 | C27: ABEOKUTA GIRLS GRAMMAR SCHOOL, ONIKOLOBO
B28: 21 | C28: ABEOKUTA GRAMMAR SCHOOL, IDI ABA
B29: 22 | C29: AGUNBIADE VICTORY HIGH SCHOOL, MAGBON
B30: 23 | C30: ANGLICAN HIGH SCHOOL, QUARRY ROAD, IBARA
B31: 24 | C31: ASERO HIGH SCHOOL, ASERO
B32: 25 | C32: BAPTIST BOYS' HIGH, SAJE
B33: 26 | C33: BAPTIST GIRLS' COLLEGE SCHOOL, IDI ABA
B34: 27 | C34: CATHOLIC COMPREHENSIVVE HIGH SCHOOL, PANSEKE, IBARA
B35: 28 | C35: EGBA COMPREHENSIVE HIGH SCHOOL, ASERO
B36: 29 | C36: GOVERNMENT SCIENCE AND TECHNICAL COLLEGE, IDI ABA
B37: 30 | C37: IGBORE HIGH SCHOOL, IGBORE
B38: 31 | C38: IJEMO-TITUN HIGH SCHOOL, HOUSING ESTATE, IBARA
... B47: 40 | C47: SAINT LEO’S COLLEGE, ONIKOKO
B49: =COUNTA(B7:B47) -> 40 | C49: =COUNTIF(#REF!, "<1001") -> #REF!

Sheet ABEOKUTA SOUTH

Sheet ABEOKUTA NORTH NEW
A1: MINISTRY OF EDUCATION, SCIENCE AND TECHNOLOGY
A2: DEPARTMENT OF SECONDARY
A3: ABEOKUTA NORTH
A5: S/N | B5: NAME OF SCHOOL
A7: JUNIOR SCHOOL
A8: 1 | B8: ARICAN CHURCH GRAMMAR SCHOOL (JNR), ITA- IYALODE
A9: 2 | B9: ARMYDAY SECONDARY SCHOOL, (JNR), ALAMALA
A10: 3 | B10: EBENEZER GRAMMAR SCHOOL, (JNR), IBEREKODO
A11: 4 | B11: GATEWAY SECONDARY SCHOOL, (JNR), ITA - EKO
A12: 5 | B12: ILUGUN HIGH SCHOOL (JNR), ELEGA
A13: 6 | B13: LAFENWA HIGH SCHOOL (JNR), LAFENWA
A14: 7 | B14: PREMIER GRAMMAR SCHOOL (JNR), LAFENWA
A15: 8 | B15: ST. PETER'S COLLEGE,(JNR) OLOMORE
A16: 9 | B16: UNITY HIGH SCHOOL,(JNR) AGO- IKA
B17: TOTAL
B18: SENIOR SCHOOL
A19: 10 | B19: ARICAN CHURCH GRAMMAR SCHOOL (SNR), ITA- IYALODE
A20: 11 | B20: ARMYDAY SECONDARY SCHOOL, (SNR), ALAMALA
A21: 12 | B21: EBENEZER GRAMMAR SCHOOL, (SNR), IBEREKODO
A22: 13 | B22: GATEWAY SECONDARY SCHOOL, (SNR), ITA - EKO
A23: 14 | B23: ILUGUN HIGH SCHOOL (SNR), ELEGA
A24: 15 | B24: LAFENWA HIGH SCHOOL (SNR), LAFENWA
A25: 16 | B25: PREMIER GRAMMAR SCHOOL (SNR), LAFENWA
A26: 17 | B26: ST. PETER'S COLLEGE,(SNR) OLOMORE
A27: 18 | B27: UNITY HIGH SCHOOL,(SNR) AGO- IKA
B28: TOTAL
B29: COMBINED SCHOOL
A30: 19 | B30: AJIBOYEDE COMPRHENSIVE HIGH SCHOOL, IBARA - ORILE
A31: 20 | B31: ANSAR-UD- DEEN GRAMMAR SCHOOL, ISAGA ORILE
A32: 21 | B32: IDI- EMI HIGH SCHOOL, IDI EMI
A33: 22 | B33: IKIJA HIGH SCHOOL, IKIJA
A34: 23 | B34: ILEWO COMMUNITY HIGH SCHOOL, ILEWO
A35: 24 | B35: IMALA COMMUNITY HIGH SCHOOL, IMALA
A36: 25 | B36: OKE- ONA GRAMMAR SCHOOL, OKE- ONA
A37: 26 | B37: OLORUNDA COMMUNITY HIGH SCHOOL, OLORUNDA
A38: 27 | B38: OLUMO HIGH SCHOOL, SABO
B42: =COUNTA(A8:A38) -> 27

Sheet ABEOKUTA NORTH
A1: MINISTRY OF EDUCATION SCIENCE AND TECHNOLOGY
A2: DEPARTMENT OF SECONDARY
A3: RUNNING COST ANALYSIS BY ZONES
A4: ABEOKUTA NORTH
A5: S/N | B5: NAME OF SCHOOLS ( IN FULL AND UPPER CASE) | G5: L.G/LCDA | J5: WARD | L5: J S S 1 | T5: J S S 2 | AC5: J S S 3 | AK5: SUB TOTAL J S S 1 - J S S 3 | AV5: S S S 1 | BB5: S S S 2 | BK5: S S S 3 | BT5: SUB TOTAL S S S 1 - S S S 3 | CP5: NUMBER OF TEACHERS
L6: ARM | N6: M | P6: F | R6: T | T6: ARM | V6: M | Y6: F | AA6: T | AC6: ARM | AE6: M | AG6: F | AI6: T | AK6: ARM | AM6: M | AO6: F | AS6: T | AV6: ARM | AW6: M | AY6: F | BA6: T | BB6: ARM | BD6: M | BF6: F | BI6: T | BK6: ARM | BM6: M | BQ6: F | BR6: T | BT6: ARM | BV6: M | BY6: F | CA6: T | CD6: ARM | CG6: M | CJ6: F | CM6: TOTAL | CP6: M | CS6: F | CV6: T | CX6: RUNNING COST @ ₦30,000 FOR LEARNERS < 1000 PER MONTH FOR 3 MONTHS & @ ₦50,000 FOR LEARNERS > 1000 PER MONTH FOR 3 MONTHS
A7: 1 | B7: AFRICAN CHURCH GRAMMAR SCHOOL(JUNIOR), ITA-IYALODE | G7: ABEOKUTA NORTH | J7: 11 | L7: 18 | N7: 561 | P7: 564 | R7: 1125 | T7: 18 | V7: 544 | Y7: 510 | AA7: 1054 | AC7: 18 | AE7: 521 | AG7: 480 | AI7: 1001 | AK7: 54 | AM7: 1626 | AO7: 1554 | AS7: 3180 | AV7: 0 | AW7: 0 | AY7: 0 | BA7: 0 | BB7: 0 | BD7: 0 | BF7: 0 | BI7: 0 | BK7: 0 | BM7: 0 | BQ7: 0 | BR7: 0 | BT7: 0 | BV7: 0 | BY7: 0 | CA7: 0 | CD7: 54 | CG7: 1626 | CJ7: 1554 | CM7: 3180 | CP7: 22 | CS7: 58 | CV7: 80 | CX7: =IF(CM7<1001,30000 * 3,50000*3) -> 150000
A8: 2 | B8: ARMY DAY SECONDARY SCHOOL(JUNIOR), ALAMALA | G8: ABEOKUTA NORTH OKE OGUN | J8: 15 | L8: 5 | N8: 183 | P8: 178 | R8: 361 | T8: 5 | V8: 189 | Y8: 167 | AA8: 356 | AC8: 2 | AE8: 89 | AG8: 72 | AI8: 161 | AK8: 12 | AM8: 461 | AO8: 417 | AS8: 878 | AV8: 0 | AW8: 0 | AY8: 0 | BA8: 0 | BB8: 0 | BD8: 0 | BF8: 0 | BI8: 0 | BK8: 0 | BM8: 0 | BQ8: 0 | BR8: 0 | BT8: 0 | BV8: 0 | BY8: 0 | CA8: 0 | CD8: 12 | CG8: 461 | CJ8: 417 | CM8: 878 | CP8: 9 | CS8: 20 | CV8: 29 | CX8: =IF(CM8<1001,30000 * 3,50000*3) -> 90000
A9: 3 | B9: EBENEZER GRAMMAR SCHOOL(JUNIOR), IBEREKODO | G9: ABEOKUTA NORTH | J9: 4 | L9: 5 | N9: 180 | P9: 191 | R9: 371 | T9: 6 | V9: 180 | Y9: 204 | AA9: 384 | AC9: 6 | AE9: 168 | AG9: 176 | AI9: 344 | AK9: 17 | AM9: 528 | AO9: 571 | AS9: 1099 | AV9: 0 | AW9: 0 | AY9: 0 | BA9: 0 | BB9: 0 | BD9: 0 | BF9: 0 | BI9: 0 | BK9: 0 | BM9: 0 | BQ9: 0 | BR9: 0 | BT9: 0 | BV9: 0 | BY9: 0 | CA9: 0 | CD9: 17 | CG9: 528 | CJ9: 571 | CM9: 1099 | CP9: 16 | CS9: 25 | CV9: 41 | CX9: =IF(CM9<1001,30000 * 3,50000*3) -> 150000
A10: 4 | B10: GATEWAY SECONDARY SCHOOL(JUNIOR), ITA- IYALODE | G10: ABEOKUTA NORTH EAST | J10: 11 | L10: 10 | N10: 202 | P10: 186 | R10: 388 | T10: 10 | V10: 169 | Y10: 184 | AA10: 353 | AC10: 10 | AE10: 175 | AG10: 154 | AI10: 329 | AK10: 30 | AM10: 546 | AO10: 524 | AS10: 1070 | AV10: 0 | AW10: 0 | AY10: 0 | BA10: 0 | BB10: 0 | BD10: 0 | BF10: 0 | BI10: 0 | BK10: 0 | BM10: 0 | BQ10: 0 | BR10: 0 | BT10: 0 | BV10: 0 | BY10: 0 | CA10: 0 | CD10: 30 | CG10: 546 | CJ10: 524 | CM10: 1070 | CP10: 14 | CS10: 35 | CV10: 49 | CX10: =IF(CM10<1001,30000 * 3,50000*3) -> 150000
A11: 5 | B11: ILUGUN HIGH SCHOOL(JUNIOR), ELEGA | G11: ABEOKUTA NORTH | J11: 4 | L11: 10 | N11: 353 | P11: 346 | R11: 699 | T11: 8 | V11: 217 | Y11: 267 | AA11: 484 | AC11: 8 | AE11: 127 | AG11: 207 | AI11: 334 | AK11: 26 | AM11: 697 | AO11: 820 | AS11: 1517 | AV11: 0 | AW11: 0 | AY11: 0 | BA11: 0 | BB11: 0 | BD11: 0 | BF11: 0 | BI11: 0 | BK11: 0 | BM11: 0 | BQ11: 0 | BR11: 0 | BT11: 0 | BV11: 0 | BY11: 0 | CA11: 0 | CD11: 26 | CG11: 697 | CJ11: 820 | CM11: 1517 | CP11: 12 | CS11: 30 | CV11: 42 | CX11: =IF(CM11<1001,30000 * 3,50000*3) -> 150000
A12: 6 | B12: LAFENWA HIGH SCHOOL(JUNIOR), LAFENWA | G12: ABEOKUTA NORTH EAST | J12: 9 | L12: 12 | N12: 359 | P12: 322 | R12: 681 | T12: 10 | V12: 236 | Y12: 267 | AA12: 503 | AC12: 8 | AE12: 191 | AG12: 185 | AI12: 376 | AK12: 30 | AM12: 786 | AO12: 774 | AS12: 1560 | AV12: 0 | AW12: 0 | AY12: 0 | BA12: 0 | BB12: 0 | BD12: 0 | BF12: 0 | BI12: 0 | BK12: 0 | BM12: 0 | BQ12: 0 | BR12: 0 | BT12: 0 | BV12: 0 | BY12: 0 | CA12: 0 | CD12: 30 | CG12: 786 | CJ12: 774 | CM12: 1560 | CP12: 8 | CS12: 42 | CV12: 50 | CX12: =IF(CM12<1001,30000 * 3,50000*3) -> 150000
A13: 7 | B13: PREMIER GRAMMAR SCHOOL(JUNIOR), LAFENWA | G13: ABEOKUTA NORTH WEST | J13: 9 | L13: 12 | N13: 356 | P13: 307 | R13: 663 | T13: 10 | V13: 260 | Y13: 233 | AA13: 493 | AC13: 10 | AE13: 263 | AG13: 245 | AI13: 508 | AK13: 32 | AM13: 879 | AO13: 785 | AS13: 1664 | AV13: 0 | AW13: 0 | AY13: 0 | BA13: 0 | BB13: 0 | BD13: 0 | BF13: 0 | BI13: 0 | BK13: 0 | BM13: 0 | BQ13: 0 | BR13: 0 | BT13: 0 | BV13: 0 | BY13: 0 | CA13: 0 | CD13: 32 | CG13: 879 | CJ13: 785 | CM13: 1664 | CP13: 15 | CS13: 36 | CV13: 51 | CX13: =IF(CM13<1001,30000 * 3,50000*3) -> 150000
A14: 8 | B14: ST' PETER'S COLLEGE(JUNIOR), OLOMORE | G14: ABEOKUTA NORTH | J14: 12 | L14: 6 | N14: 205 | P14: 235 | R14: 440 | T14: 7 | V14: 176 | Y14: 202 | AA14: 378 | AC14: 6 | AE14: 160 | AG14: 201 | AI14: 361 | AK14: 19 | AM14: 541 | AO14: 638 | AS14: 1179 | AV14: 0 | AW14: 0 | AY14: 0 | BA14: 0 | BB14: 0 | BD14: 0 | BF14: 0 | BI14: 0 | BK14: 0 | BM14: 0 | BQ14: 0 | BR14: 0 | BT14: 0 | BV14: 0 | BY14: 0 | CA14: 0 | CD14: 19 | CG14: 541 | CJ14: 638 | CM14: 1179 | CP14: 17 | CS14: 44 | CV14: 61 | CX14: =IF(CM14<1001,30000 * 3,50000*3) -> 150000
A15: 9 | B15: UNITY HIGH SCHOOL(JUNIOR), AGO-IKA | G15: ABEOKUTA NORTH | J15: 9 | L15: 10 | N15: 278 | P15: 222 | R15: 500 | T15: 10 | V15: 217 | Y15: 241 | AA15: 458 | AC15: 10 | AE15: 187 | AG15: 192 | AI15: 379 | AK15: 30 | AM15: 682 | AO15: 655 | AS15: 1337 | AV15: 0 | AW15: 0 | AY15: 0 | BA15: 0 | BB15: 0 | BD15: 0 | BF15: 0 | BI15: 0 | BK15: 0 | BM15: 0 | BQ15: 0 | BR15: 0 | BT15: 0 | BV15: 0 | BY15: 0 | CA15: 0 | CD15: 30 | CG15: 682 | CJ15: 655 | CM15: 1337 | CP15: 7 | CS15: 34 | CV15: 41 | CX15: =IF(CM15<1001,30000 * 3,50000*3) -> 150000
A16: 10 | B16: AFRICAN CHURCH GRAMMAR SCHOOL(SENIOR), ITA-IYALODE | G16: ABEOKUTA NORTH | J16: 11 | L16: 0 | N16: 0 | P16: 0 | R16: 0 | T16: 0 | V16: 0 | Y16: 0 | AA16: 0 | AC16: 0 | AE16: 0 | AG16: 0 | AI16: 0 | AK16: 0 | AM16: 0 | AO16: 0 | AS16: 0 | AV16: 18 | AW16: 585 | AY16: 515 | BA16: 1100 | BB16: 18 | BD16: 444 | BF16: 409 | BI16: 853 | BK16: 12 | BM16: 278 | BQ16: 302 | BR16: 580 | BT16: 48 | BV16: 1307 | BY16: 1226 | CA16: 2533 | CD16: 48 | CG16: 1307 | CJ16: 1226 | CM16: 2533 | CP16: 26 | CS16: 25 | CV16: 51 | CX16: =IF(CM16<1001,30000 * 3,50000*3) -> 150000
A17: 11 | B17: ARMY DAY SECONDARY SCHOOL(SENIOR), ALAMALA | G17: ABEOKUTA NORTH OKE OGUN | J17: 15 | L17: 0 | N17: 0 | P17: 0 | R17: 0 | T17: 0 | V17: 0 | Y17: 0 | AA17: 0 | AC17: 0 | AE17: 0 | AG17: 0 | AI17: 0 | AK17: 0 | AM17: 0 | AO17: 0 | AS17: 0 | AV17: 4 | AW17: 94 | AY17: 93 | BA17: 187 | BB17: 3 | BD17: 62 | BF17: 56 | BI17: 118 | BK17: 3 | BM17: 59 | BQ17: 72 | BR17: 131 | BT17: 10 | BV17: 215 | BY17: 221 | CA17: 436 | CD17: 10 | CG17: 215 | CJ17: 221 | CM17: 436 | CP17: 9 | CS17: 15 | CV17: 24 | CX17: =IF(CM17<1001,30000 * 3,50000*3) -> 90000
A18: 12 | B18: EBENEZER GRAMMAR SCHOOL(SENIOR), IBEREKODO | G18: ABEOKUTA NORTH | J18: 4 | L18: 0 | N18: 0 | P18: 0 | R18: 0 | T18: 0 | V18: 0 | Y18: 0 | AA18: 0 | AC18: 0 | AE18: 0 | AG18: 0 | AI18: 0 | AK18: 0 | AM18: 0 | AO18: 0 | AS18: 0 | AV18: 5 | AW18: 164 | AY18: 225 | BA18: 389 | BB18: 5 | BD18: 142 | BF18: 203 | BI18: 345 | BK18: 3 | BM18: 104 | BQ18: 122 | BR18: 226 | BT18: 13 | BV18: 410 | BY18: 550 | CA18: 960 | CD18: 13 | CG18: 410 | CJ18: 550 | CM18: 960 | CP18: 12 | CS18: 19 | CV18: 31 | CX18: =IF(CM18<1001,30000 * 3,50000*3) -> 90000
... A23: 17 | B23: ST' PETER'S COLLEGE(SENIOR), OLOMORE | G23: ABEOKUTA NORTH | J23: 12 | L23: 0 | N23: 0 | P23: 0 | R23: 0 | T23: 0 | V23: 0 | Y23: 0 | AA23: 0 | AC23: 0 | AE23: 0 | AG23: 0 | AI23: 0 | AK23: 0 | AM23: 0 | AO23: 0 | AS23: 0 | AV23: 6 | AW23: 190 | AY23: 210 | BA23: 400 | BB23: 7 | BD23: 169 | BF23: 210 | BI23: 379 | BK23: 6 | BM23: 94 | BQ23: 104 | BR23: 198 | BT23: 19 | BV23: 453 | BY23: 524 | CA23: 977 | CD23: 19 | CG23: 453 | CJ23: 524 | CM23: 977 | CP23: 20 | CS23: 29 | CV23: 49 | CX23: =IF(CM23<1001,30000 * 3,50000*3) -> 90000
A24: 18 | B24: UNITY HIGH SCHOOL(SENIOR), AGO-IKA | G24: ABEOKUTA NORTH | J24: 9 | L24: 0 | N24: 0 | P24: 0 | R24: 0 | T24: 0 | V24: 0 | Y24: 0 | AA24: 0 | AC24: 0 | AE24: 0 | AG24: 0 | AI24: 0 | AK24: 0 | AM24: 0 | AO24: 0 | AS24: 0 | AV24: 11 | AW24: 228 | AY24: 202 | BA24: 430 | BB24: 9 | BD24: 134 | BF24: 150 | BI24: 284 | BK24: 3 | BM24: 29 | BQ24: 49 | BR24: 78 | BT24: 23 | BV24: 391 | BY24: 401 | CA24: 792 | CD24: 23 | CG24: 391 | CJ24: 401 | CM24: 792 | CP24: 15 | CS24: 20 | CV24: 35 | CX24: =IF(CM24<1001,30000 * 3,50000*3) -> 90000 | DA24: =C37=COUNTIF(B7:F32,"GOVERNMENT SCIENCE") -> TRUE
A25: 19 | B25: ANSAR-U-DEEN GRAMMAR SCHOOL, ISHAGA | G25: ABEOKUTA NORTH OKE OGUN | J25: 15 | L25: 2 | N25: 26 | P25: 22 | R25: 48 | T25: 2 | V25: 24 | Y25: 27 | AA25: 51 | AC25: 2 | AE25: 19 | AG25: 19 | AI25: 38 | AK25: 6 | AM25: 69 | AO25: 68 | AS25: 137 | AV25: 1 | AW25: 21 | AY25: 22 | BA25: 43 | BB25: 1 | BD25: 18 | BF25: 13 | BI25: 31 | BK25: 1 | BM25: 13 | BQ25: 13 | BR25: 26 | BT25: 3 | BV25: 52 | BY25: 48 | CA25: 100 | CD25: 9 | CG25: 121 | CJ25: 116 | CM25: 237 | CP25: 15 | CS25: 10 | CV25: 25 | CX25: =IF(CM25<1001,30000 * 3,50000*3) -> 90000
A26: 20 | B26: ILEWO HIGH SCHOOL, ILEWO-ORILE | G26: ABEOKUTA NORTH OKE OGUN | J26: 16 | L26: 1 | N26: 18 | P26: 15 | R26: 33 | T26: 1 | V26: 18 | Y26: 22 | AA26: 40 | AC26: 1 | AE26: 24 | AG26: 12 | AI26: 36 | AK26: 3 | AM26: 60 | AO26: 49 | AS26: 109 | AV26: 1 | AW26: 17 | AY26: 13 | BA26: 30 | BB26: 1 | BD26: 18 | BF26: 14 | BI26: 32 | BK26: 1 | BM26: 17 | BQ26: 8 | BR26: 25 | BT26: 3 | BV26: 52 | BY26: 35 | CA26: 87 | CD26: 6 | CG26: 112 | CJ26: 84 | CM26: 196 | CP26: 8 | CS26: 7 | CV26: 15 | CX26: =IF(CM26<1001,30000 * 3,50000*3) -> 90000
A27: 21 | B27: IDI-EMI HIGH SCHOOL, IDI-EMI | G27: ABEOKUTA NORTH OKE OGUN | J27: 10 | L27: 1 | N27: 35 | P27: 22 | R27: 57 | T27: 2 | V27: 46 | Y27: 19 | AA27: 65 | AC27: 2 | AE27: 36 | AG27: 25 | AI27: 61 | AK27: 5 | AM27: 117 | AO27: 66 | AS27: 183 | AV27: 2 | AW27: 26 | AY27: 16 | BA27: 42 | BB27: 1 | BD27: 24 | BF27: 10 | BI27: 34 | BK27: 1 | BM27: 24 | BQ27: 7 | BR27: 31 | BT27: 4 | BV27: 74 | BY27: 33 | CA27: 107 | CD27: 9 | CG27: 191 | CJ27: 99 | CM27: 290 | CP27: 6 | CS27: 2 | CV27: 8 | CX27: =IF(CM27<1001,30000 * 3,50000*3) -> 90000
A28: 22 | B28: IKIJA HIGH SCHOOL, IBEREKODO | G28: ABEOKUTA NORTH | J28: 2 | L28: 4 | N28: 69 | P28: 69 | R28: 138 | T28: 4 | V28: 118 | Y28: 112 | AA28: 230 | AC28: 4 | AE28: 63 | AG28: 88 | AI28: 151 | AK28: 12 | AM28: 250 | AO28: 269 | AS28: 519 | AV28: 3 | AW28: 100 | AY28: 82 | BA28: 182 | BB28: 3 | BD28: 55 | BF28: 66 | BI28: 121 | BK28: 3 | BM28: 21 | BQ28: 30 | BR28: 51 | BT28: 9 | BV28: 176 | BY28: 178 | CA28: 354 | CD28: 21 | CG28: 426 | CJ28: 447 | CM28: 873 | CP28: 19 | CS28: 23 | CV28: 42 | CX28: =IF(CM28<1001,30000 * 3,50000*3) -> 90000
A29: 23 | B29: IMALA COMMUNITY HUGH SCHOOL, IMALA | G29: ABEOKUTA NORTH | J29: 14 | L29: 2 | N29: 47 | P29: 29 | R29: 76 | T29: 2 | V29: 43 | Y29: 28 | AA29: 71 | AC29: 1 | AE29: 15 | AG29: 13 | AI29: 28 | AK29: 5 | AM29: 105 | AO29: 70 | AS29: 175 | AV29: 1 | AW29: 18 | AY29: 19 | BA29: 37 | BB29: 2 | BD29: 29 | BF29: 19 | BI29: 48 | BK29: 1 | BM29: 20 | BQ29: 14 | BR29: 34 | BT29: 4 | BV29: 67 | BY29: 52 | CA29: 119 | CD29: 9 | CG29: 172 | CJ29: 122 | CM29: 294 | CP29: 6 | CS29: 6 | CV29: 12 | CX29: =IF(CM29<1001,30000 * 3,50000*3) -> 90000
A30: 24 | B30: OKE-ONA GRAMMAR SCHOOL, AKOMOJE | G30: ABEOKUTA NORTH | J30: 5 | L30: 3 | N30: 106 | P30: 91 | R30: 197 | T30: 3 | V30: 76 | Y30: 87 | AA30: 163 | AC30: 3 | AE30: 58 | AG30: 59 | AI30: 117 | AK30: 9 | AM30: 240 | AO30: 237 | AS30: 477 | AV30: 2 | AW30: 59 | AY30: 58 | BA30: 117 | BB30: 2 | BD30: 28 | BF30: 25 | BI30: 53 | BK30: 2 | BM30: 26 | BQ30: 30 | BR30: 56 | BT30: 6 | BV30: 113 | BY30: 113 | CA30: 226 | CD30: 15 | CG30: 353 | CJ30: 350 | CM30: 703 | CP30: 21 | CS30: 11 | CV30: 32 | CX30: =IF(CM30<1001,30000 * 3,50000*3) -> 90000
A31: 25 | B31: OLORUNDA COMMUNITY HIGH SCHOOL, OLORUNDA | G31: ABEOKUTA NORTH OKE OGUN | J31: 13 | L31: 2 | N31: 42 | P31: 38 | R31: 80 | T31: 2 | V31: 51 | Y31: 37 | AA31: 88 | AC31: 2 | AE31: 22 | AG31: 24 | AI31: 46 | AK31: 6 | AM31: 115 | AO31: 99 | AS31: 214 | AV31: 2 | AW31: 22 | AY31: 27 | BA31: 49 | BB31: 2 | BD31: 21 | BF31: 14 | BI31: 35 | BK31: 1 | BM31: 12 | BQ31: 15 | BR31: 27 | BT31: 5 | BV31: 55 | BY31: 56 | CA31: 111 | CD31: 11 | CG31: 170 | CJ31: 155 | CM31: 325 | CP31: 11 | CS31: 11 | CV31: 22 | CX31: =IF(CM31<1001,30000 * 3,50000*3) -> 90000
A32: 26 | B32: OLUMO HIGH SCHOOL, SABO, ABEOKUTA | G32: ABEOKUTA NORTH | J32: 11 | L32: 7 | N32: 219 | P32: 134 | R32: 353 | T32: 6 | V32: 171 | Y32: 186 | AA32: 357 | AC32: 6 | AE32: 159 | AG32: 160 | AI32: 319 | AK32: 19 | AM32: 549 | AO32: 480 | AS32: 1029 | AV32: 5 | AW32: 118 | AY32: 124 | BA32: 242 | BB32: 4 | BD32: 95 | BF32: 131 | BI32: 226 | BK32: 4 | BM32: 55 | BQ32: 78 | BR32: 133 | BT32: 13 | BV32: 268 | BY32: 333 | CA32: 601 | CD32: 32 | CG32: 817 | CJ32: 813 | CM32: 1630 | CP32: 17 | CS32: 28 | CV32: 45 | CX32: =IF(CM32<1001,30000 * 3,50000*3) -> 150000
B33: TOTAL | CG33: =SUM(CG7:CI32) -> 13711 | CJ33: =SUM(CJ7:CL32) -> 13990 | CM33: =SUM(CM7:CO32) -> 27701 | CX33: =SUM(CX7:CX32) -> 3000000
F34: AMOUNT DUE FOR ZEO @ ₦20 per learner = | CX34: =CM33*20 -> 554020 | DE34: =CP33*20 -> 0
F35: TOTAL RUNNING COST REQUIRED FOR ABEOKUTA NORTH | CX35: =CX33+CX34 -> 3554020 | DE35: =DE33+DE34 -> 0
F36: NO OF SCHOOLS WITH LEARNERS < 1000 | CG36: ='ABEOKUTA SOUTH NEW'!C49 -> #REF! | CH36: =COUNTIF(CL6:CM32, ">1000") -> 11 | CI36: =COUNTIF(CN6:CO53, "<1000") -> 0
B37: =COUNTA(B7:F32)-COUNTIF(B7:F32,"GOVERNMENT SCIENCE") -> 26 | C37: =COUNTIF(B7:F32,"GOVERNMENT SCIENCE") -> 0

Sheet Yewa South new
A1: MINISTRY OF EDUCATION SCIENCE AND TECHNOLOGY
A2: DEPARTMENT OF SECONDARY RUNNING COST ANALYSIS BY ZONES
A3: YEWA SOUTH
A4: S/N | B4: NAME OF SCHOOL | C4: NAME OF PRINCIPAL | D4: PRINCIPAL'S PHONE NUMBER
B5: JUNIOR SCHOOLS
A6: 1 | B6: ARMY DAY JUNIOR SEC. SCH,. OWODE | C6: MR OMOLE ,K | D6: 08060534444
A7: 2 | B7: AREA COMM. HIGH SCH., JNR, OWODE | C7: MR OLALEYE | D7: 08066635448
A8: 3 | B8: OWODE SEC. SCHOOL JNR., OWODE | C8: MR TELLA K.H | D8: 08029595745
A9: 4 | B9: IYEWA HIGH SCHOOL JNR. AJILETE | C9: Ag. MR RAJI AKEEM O, | D9: 08025926348
A10: 5 | B10: MUSLIM PROG. HIGH SCH., OKE-ODAN | C10: Ag. MR ALEGBELEYE | D10: 07083038065
A11: 6 | B11: EMMANUEL COMM. HIGH SCH., ILARO | C11: MR MASONWO | D11: 08038579250
A12: 7 | B12: ORONNA HIGH SCHOOL, JNR, ILARO | C12: MRS OKOYE | D12: 08036654227
A13: 8 | B13: ANGLICAN GRAMM, SCH. ILARO | C13: MR AKINYEMI ,F | D13: 08036083145
A14: 9 | B14: ITOLU COMM. H/S JUNIOR, ILARO | C14: MRS OKPARAVERO .A | D14: 08039746389
A15: 10 | B15: YEWA COLLEGE JUNIOR, ILARO | C15: MRS ADENIJOR | D15: 08034346428
A16: 11 | B16: IWOYE AREA COMM. H/S, IWOYE. | C16: MR ADELOYE J.A | D16: 08060972552
B17: TOTAL
B18: SENIOR SCHOOLS
A19: 12 | B19: ARMY DAY SENIOR SEC. SCH,. OWODE | C19: ALH.ADESAKIN | D19: 07030200205
A20: 13 | B20: AREA COMM. HIGH SCH., SNR, OWODE | C20: MR AKINOLA | D20: 08038060719
A21: 14 | B21: OWODE SEC. SCHOOL SNR., OWODE | C21: MISS BABARINSA | D21: 08036832601
A22: 15 | B22: IYEWA HIGH SCHOOL SNR. AJILETE | C22: MR OYEGOKE JULIUS. O | D22: 07031378421
A23: 16 | B23: MUSLIM PROG. HIGH SCH., OKE-ODAN | C23: MR SALAMI, A.A | D23: 08065305695
A24: 17 | B24: EMMANUEL COMM. HIGH SCH., ILARO | C24: MR OLUMOMI | D24: 08108871828
A25: 18 | B25: ORONNA HIGH SCHOOL, SNR, ILARO | C25: MR ADENIJO | D25: 08033681855
A26: 19 | B26: ANGLICAN GRAMM, SCH. ILARO | C26: MRS.BOLANLE A.O | D26: 08030691023
A27: 20 | B27: ITOLU COMM. H/S SENIOR, ILARO | C27: MR SALAMI ,A.T | D27: 08034734111
A28: 21 | B28: YEWA COLLEGE SENIOR, ILARO | C28: MR ELEGBEDE A | D28: 08035756506
A29: 22 | B29: IWOYE AREA COMM. H/S, IWOYE. | C29: Ag. MR ADEYEMO B. K | D29: 08038162463
B30: TOTAL
B31: COMBINED SCHOOLS
A32: 23 | B32: AREA COMM. HIGH SCH., OLOKUTA | C32: MRS SALAMI | D32: 08025314961
A33: 24 | B33: BAPTIST HIGH SCHOOL,ILARO | C33: MRS ADELEYE | D33: 08035030518
A34: 25 | B34: ILOBI/ERINJA COMM.HIGH SCH ILOBI | C34: MR ADAMS | D34: 08106459502
A35: 26 | B35: IDOGO/IPAJA COMM.HIGH SCH,IDGO | C35: MR OLADUNJOYE, I. A | D35: 08039059319
A36: 27 | B36: OKE - ODAN GRAM. SCH,OKE-ODAN | C36: MR RUNSEWE. S.O | D36: 08023974201
A37: 28 | B37: OWO COMMUNITY HIGH SCH.OWO | C37: Ag NR ABORODE | D37: 08036812859
B38: TOTAL
B41: =COUNTA(A6:A37) -> 28

Sheet YEWA SOUTH
A1: MINISTRY OF EDUCATION SCIENCE AND TECHNOLOGY
A2: DEPARTMENT OF SECONDARY RUNNING COST ANALYSIS BY ZONES
A3: RUNNING COST ANALYSIS
A4: YEWA SOUTH
A5: S/N | B5: NAME OF SCHOOLS ( IN FULL AND UPPER CASE) | F5: L.G/LCDA | I5: WARD | K5: J S S 1 | S5: J S S 2 | AC5: J S S 3 | AK5: SUB TOTAL J S S 1 - J S S 3 | AV5: S S S 1 | BC5: S S S 2 | BM5: S S S 3 | BU5: SUB TOTAL S S S 1 - S S S 3 | CP5: NUMBER OF TEACHERS | CW5: STATUS
K6: ARM | M6: M | O6: F | Q6: T | S6: ARM | U6: M | X6: F | AA6: T | AC6: ARM | AE6: M | AG6: F | AI6: T | AK6: ARM | AM6: M | AO6: F | AS6: T | AV6: ARM | AX6: M | AZ6: F | BA6: T | BC6: ARM | BD6: M | BG6: F | BI6: T | BM6: ARM | BO6: M | BR6: F | BT6: T | BU6: ARM | BX6: M | BZ6: F | CB6: T | CE6: ARM | CH6: M | CK6: F | CN6: T | CP6: M | CS6: F | CU6: T | DA6: RUNNING COST @ ₦30,000 FOR LEARNERS < 1000 PER MONTH FOR 3 MONTHS & @ ₦50,000 FOR LEARNERS > 1000 PER MONTH FOR 3 MONTHS
A7: 1 | B7: Anglican Grammer School(Jr), Ilaro | F7: Ilaro | I7: Ilaro 1 | K7: 4 | M7: 188 | O7: 184 | Q7: 372 | S7: 4 | U7: 181 | X7: 161 | AA7: 342 | AC7: 3 | AE7: 130 | AG7: 144 | AI7: 274 | AK7: 11 | AM7: 499 | AO7: 489 | AS7: 988 | AV7: 0 | AX7: 0 | AZ7: 0 | BA7: 0 | BC7: 0 | BD7: 0 | BG7: 0 | BI7: 0 | BM7: 0 | BO7: 0 | BR7: 0 | BT7: 0 | BU7: 0 | BX7: 0 | BZ7: 0 | CB7: 0 | CE7: 11 | CH7: 499 | CK7: 489 | CN7: 988 | CP7: 5 | CS7: 16 | CU7: 21 | CW7: SUCCESS | DA7: =IF(CN7<1001,30000 * 3,50000*3) -> 90000
A8: 2 | B8: Area Community High School (Jr), Owode | F8: Ifekowaju | I8: Owode 1 | K8: 8 | M8: 387 | O8: 408 | Q8: 795 | S8: 8 | U8: 407 | X8: 398 | AA8: 805 | AC8: 7 | AE8: 420 | AG8: 432 | AI8: 852 | AK8: 23 | AM8: 1214 | AO8: 1238 | AS8: 2452 | AV8: 0 | AX8: 0 | AZ8: 0 | BA8: 0 | BC8: 0 | BD8: 0 | BG8: 0 | BI8: 0 | BM8: 0 | BO8: 0 | BR8: 0 | BT8: 0 | BU8: 0 | BX8: 0 | BZ8: 0 | CB8: 0 | CE8: 23 | CH8: 1214 | CK8: 1238 | CN8: 2452 | CP8: 13 | CS8: 17 | CU8: 30 | CW8: SUCCESS | DA8: =IF(CN8<1001,30000 * 3,50000*3) -> 150000
A9: 3 | B9: Army Day Secondary School (Jr), Owode | F9: Ifekowaju | I9: Owode2 | K9: 4 | M9: 279 | O9: 238 | Q9: 517 | S9: 6 | U9: 316 | X9: 387 | AA9: 703 | AC9: 4 | AE9: 257 | AG9: 249 | AI9: 506 | AK9: 14 | AM9: 852 | AO9: 874 | AS9: 1726 | AV9: 0 | AX9: 0 | AZ9: 0 | BA9: 0 | BC9: 0 | BD9: 0 | BG9: 0 | BI9: 0 | BM9: 0 | BO9: 0 | BR9: 0 | BT9: 0 | BU9: 0 | BX9: 0 | BZ9: 0 | CB9: 0 | CE9: 14 | CH9: 852 | CK9: 874 | CN9: 1726 | CP9: 13 | CS9: 15 | CU9: 28 | CW9: SUCCESS | DA9: =IF(CN9<1001,30000 * 3,50000*3) -> 150000
A10: 4 | B10: Emmanuel Commercial High School(Jr), Ilaro | F10: Ilaro | I10: Ilaro 3 | K10: 2 | M10: 57 | O10: 37 | Q10: 94 | S10: 2 | U10: 42 | X10: 42 | AA10: 84 | AC10: 2 | AE10: 42 | AG10: 38 | AI10: 80 | AK10: 6 | AM10: 141 | AO10: 117 | AS10: 258 | AV10: 0 | AX10: 0 | AZ10: 0 | BA10: 0 | BC10: 0 | BD10: 0 | BG10: 0 | BI10: 0 | BM10: 0 | BO10: 0 | BR10: 0 | BT10: 0 | BU10: 0 | BX10: 0 | BZ10: 0 | CB10: 0 | CE10: 6 | CH10: 141 | CK10: 117 | CN10: 258 | CP10: 3 | CS10: 10 | CU10: 13 | CW10: SUCCESS | DA10: =IF(CN10<1001,30000 * 3,50000*3) -> 90000
A11: 5 | B11: Itolu Community High School(Jr), Ilaro | F11: Ilaro | I11: Ilaro 3 | K11: 6 | M11: 277 | O11: 289 | Q11: 566 | S11: 6 | U11: 293 | X11: 298 | AA11: 591 | AC11: 6 | AE11: 209 | AG11: 196 | AI11: 405 | AK11: 18 | AM11: 779 | AO11: 783 | AS11: 1562 | AV11: 0 | AX11: 0 | AZ11: 0 | BA11: 0 | BC11: 0 | BD11: 0 | BG11: 0 | BI11: 0 | BM11: 0 | BO11: 0 | BR11: 0 | BT11: 0 | BU11: 0 | BX11: 0 | BZ11: 0 | CB11: 0 | CE11: 18 | CH11: 779 | CK11: 783 | CN11: 1562 | CP11: 5 | CS11: 18 | CU11: 23 | CW11: SUCCESS | DA11: =IF(CN11<1001,30000 * 3,50000*3) -> 150000
A12: 6 | B12: Iwoye Area Community High School(Jr), Iwoye | F12: Ilaro | I12: Iwoye | K12: 2 | M12: 91 | O12: 59 | Q12: 150 | S12: 2 | U12: 63 | X12: 47 | AA12: 110 | AC12: 2 | AE12: 50 | AG12: 52 | AI12: 102 | AK12: 6 | AM12: 204 | AO12: 158 | AS12: 362 | AV12: 0 | AX12: 0 | AZ12: 0 | BA12: 0 | BC12: 0 | BD12: 0 | BG12: 0 | BI12: 0 | BM12: 0 | BO12: 0 | BR12: 0 | BT12: 0 | BU12: 0 | BX12: 0 | BZ12: 0 | CB12: 0 | CE12: 6 | CH12: 204 | CK12: 158 | CN12: 362 | CP12: 3 | CS12: 2 | CU12: 5 | CW12: SUCCESS | DA12: =IF(CN12<1001,30000 * 3,50000*3) -> 90000
A13: 7 | B13: Iyewa High School(Jr), Ajilete | F13: Ifekowaju | I13: Ajilete | K13: 3 | M13: 115 | O13: 88 | Q13: 203 | S13: 3 | U13: 108 | X13: 106 | AA13: 214 | AC13: 3 | AE13: 73 | AG13: 79 | AI13: 152 | AK13: 9 | AM13: 296 | AO13: 273 | AS13: 569 | AV13: 0 | AX13: 0 | AZ13: 0 | BA13: 0 | BC13: 0 | BD13: 0 | BG13: 0 | BI13: 0 | BM13: 0 | BO13: 0 | BR13: 0 | BT13: 0 | BU13: 0 | BX13: 0 | BZ13: 0 | CB13: 0 | CE13: 9 | CH13: 296 | CK13: 273 | CN13: 569 | CP13: 3 | CS13: 7 | CU13: 10 | CW13: SUCCESS | DA13: =IF(CN13<1001,30000 * 3,50000*3) -> 90000
A14: 8 | B14: Muslim Progressive High School(Jr), Oke - Odan | F14: Ifekowaju | I14: Oke Odan | K14: 2 | M14: 61 | O14: 69 | Q14: 130 | S14: 2 | U14: 66 | X14: 57 | AA14: 123 | AC14: 2 | AE14: 57 | AG14: 75 | AI14: 132 | AK14: 6 | AM14: 184 | AO14: 201 | AS14: 385 | AV14: 0 | AX14: 0 | AZ14: 0 | BA14: 0 | BC14: 0 | BD14: 0 | BG14: 0 | BI14: 0 | BM14: 0 | BO14: 0 | BR14: 0 | BT14: 0 | BU14: 0 | BX14: 0 | BZ14: 0 | CB14: 0 | CE14: 6 | CH14: 184 | CK14: 201 | CN14: 385 | CP14: 6 | CS14: 12 | CU14: 18 | CW14: SUCCESS | DA14: =IF(CN14<1001,30000 * 3,50000*3) -> 90000
A15: 9 | B15: Oronna High School(Jr), Ilaro | F15: Ilaro | I15: Ilaro 2 | K15: 6 | M15: 140 | O15: 125 | Q15: 265 | S15: 7 | U15: 156 | X15: 135 | AA15: 291 | AC15: 7 | AE15: 135 | AG15: 127 | AI15: 262 | AK15: 20 | AM15: 431 | AO15: 387 | AS15: 818 | AV15: 0 | AX15: 0 | AZ15: 0 | BA15: 0 | BC15: 0 | BD15: 0 | BG15: 0 | BI15: 0 | BM15: 0 | BO15: 0 | BR15: 0 | BT15: 0 | BU15: 0 | BX15: 0 | BZ15: 0 | CB15: 0 | CE15: 20 | CH15: 431 | CK15: 387 | CN15: 818 | CP15: 10 | CS15: 15 | CU15: 25 | CW15: SUCCESS | DA15: =IF(CN15<1001,30000 * 3,50000*3) -> 90000
A16: 10 | B16: Owode Secondary School(Jr), Owode | F16: Ifekowaju | I16: Owode2 | K16: 7 | M16: 280 | O16: 221 | Q16: 501 | S16: 5 | U16: 193 | X16: 182 | AA16: 375 | AC16: 6 | AE16: 198 | AG16: 216 | AI16: 414 | AK16: 18 | AM16: 671 | AO16: 619 | AS16: 1290 | AV16: 0 | AX16: 0 | AZ16: 0 | BA16: 0 | BC16: 0 | BD16: 0 | BG16: 0 | BI16: 0 | BM16: 0 | BO16: 0 | BR16: 0 | BT16: 0 | BU16: 0 | BX16: 0 | BZ16: 0 | CB16: 0 | CE16: 18 | CH16: 671 | CK16: 619 | CN16: 1290 | CP16: 6 | CS16: 9 | CU16: 15 | CW16: SUCCESS | DA16: =IF(CN16<1001,30000 * 3,50000*3) -> 150000
A17: 11 | B17: Yewa College(Jr), Ilaro | F17: Ilaro | I17: Ilaro 1 | K17: 7 | M17: 254 | O17: 243 | Q17: 497 | S17: 6 | U17: 200 | X17: 240 | AA17: 440 | AC17: 6 | AE17: 208 | AG17: 187 | AI17: 395 | AK17: 19 | AM17: 662 | AO17: 670 | AS17: 1332 | AV17: 0 | AX17: 0 | AZ17: 0 | BA17: 0 | BC17: 0 | BD17: 0 | BG17: 0 | BI17: 0 | BM17: 0 | BO17: 0 | BR17: 0 | BT17: 0 | BU17: 0 | BX17: 0 | BZ17: 0 | CB17: 0 | CE17: 19 | CH17: 662 | CK17: 670 | CN17: 1332 | CP17: 15 | CS17: 28 | CU17: 43 | CW17: SUCCESS | DA17: =IF(CN17<1001,30000 * 3,50000*3) -> 150000
A18: 12 | B18: Anglican Grammer School(Snr), Ilaro | F18: Ilaro | I18: Ilaro 1 | K18: 0 | M18: 0 | O18: 0 | Q18: 0 | S18: 0 | U18: 0 | X18: 0 | AA18: 0 | AC18: 0 | AE18: 0 | AG18: 0 | AI18: 0 | AK18: 0 | AM18: 0 | AO18: 0 | AS18: 0 | AV18: 4 | AX18: 99 | AZ18: 117 | BA18: 216 | BC18: 4 | BD18: 109 | BG18: 109 | BI18: 218 | BM18: 4 | BO18: 75 | BR18: 66 | BT18: 141 | BU18: 12 | BX18: 283 | BZ18: 292 | CB18: 575 | CE18: 12 | CH18: 283 | CK18: 292 | CN18: 575 | CP18: 14 | CS18: 10 | CU18: 24 | CW18: SUCCESS | DA18: =IF(CN18<1001,30000 * 3,50000*3) -> 90000
... A29: 23 | B29: Area Community High School , Olokuta | F29: Ilaro | I29: Idogo | K29: 2 | M29: 45 | O29: 29 | Q29: 74 | S29: 1 | U29: 29 | X29: 36 | AA29: 65 | AC29: 1 | AE29: 24 | AG29: 25 | AI29: 49 | AK29: 4 | AM29: 98 | AO29: 90 | AS29: 188 | AV29: 1 | AX29: 24 | AZ29: 17 | BA29: 41 | BC29: 1 | BD29: 31 | BG29: 27 | BI29: 58 | BM29: 1 | BO29: 9 | BR29: 16 | BT29: 25 | BU29: 3 | BX29: 64 | BZ29: 60 | CB29: 124 | CE29: 7 | CH29: 162 | CK29: 150 | CN29: 312 | CP29: 4 | CS29: 2 | CU29: 6 | CW29: SUCCESS | DA29: =IF(CN29<1001,30000 * 3,50000*3) -> 90000
A30: 24 | B30: Baptist High School, Ilaro | F30: Ilaro | I30: Ilaro 3 | K30: 2 | M30: 75 | O30: 53 | Q30: 128 | S30: 2 | U30: 97 | X30: 63 | AA30: 160 | AC30: 2 | AE30: 51 | AG30: 52 | AI30: 103 | AK30: 6 | AM30: 223 | AO30: 168 | AS30: 391 | AV30: 2 | AX30: 56 | AZ30: 78 | BA30: 134 | BC30: 2 | BD30: 52 | BG30: 34 | BI30: 86 | BM30: 1 | BO30: 38 | BR30: 37 | BT30: 75 | BU30: 5 | BX30: 146 | BZ30: 149 | CB30: 295 | CE30: 11 | CH30: 369 | CK30: 317 | CN30: 686 | CP30: 6 | CS30: 11 | CU30: 17 | CW30: SUCCESS | DA30: =CN30*150 -> 102900
A31: 25 | B31: Idogo/Ipaja Area Community High School, Idogo | F31: Ilaro | I31: Idogo | K31: 1 | M31: 31 | O31: 19 | Q31: 50 | S31: 1 | U31: 29 | X31: 26 | AA31: 55 | AC31: 1 | AE31: 31 | AG31: 27 | AI31: 58 | AK31: 3 | AM31: 91 | AO31: 72 | AS31: 163 | AV31: 1 | AX31: 22 | AZ31: 23 | BA31: 45 | BC31: 1 | BD31: 27 | BG31: 23 | BI31: 50 | BM31: 1 | BO31: 32 | BR31: 18 | BT31: 50 | BU31: 3 | BX31: 81 | BZ31: 64 | CB31: 145 | CE31: 6 | CH31: 172 | CK31: 136 | CN31: 308 | CP31: 5 | CS31: 2 | CU31: 7 | CW31: SUCCESS | DA31: =CN31*150 -> 46200
A32: 26 | B32: Oke - Odan Grammer School, Oke - Odan | F32: Ifekowaju | I32: Oke Odan | K32: 3 | M32: 102 | O32: 89 | Q32: 191 | S32: 3 | U32: 84 | X32: 80 | AA32: 164 | AC32: 2 | AE32: 62 | AG32: 68 | AI32: 130 | AK32: 8 | AM32: 248 | AO32: 237 | AS32: 485 | AV32: 3 | AX32: 101 | AZ32: 77 | BA32: 178 | BC32: 2 | BD32: 74 | BG32: 81 | BI32: 155 | BM32: 2 | BO32: 38 | BR32: 48 | BT32: 86 | BU32: 7 | BX32: 213 | BZ32: 206 | CB32: 419 | CE32: 15 | CH32: 461 | CK32: 443 | CN32: 904 | CP32: 15 | CS32: 5 | CU32: 20 | CW32: SUCCESS | DA32: =CN32*150 -> 135600
A33: 27 | B33: Owo Area Community High School, Owo | F33: Ifekowaju | I33: Owo | K33: 1 | M33: 30 | O33: 31 | Q33: 61 | S33: 1 | U33: 36 | X33: 26 | AA33: 62 | AC33: 1 | AE33: 23 | AG33: 20 | AI33: 43 | AK33: 3 | AM33: 89 | AO33: 77 | AS33: 166 | AV33: 1 | AX33: 24 | AZ33: 16 | BA33: 40 | BC33: 1 | BD33: 17 | BG33: 18 | BI33: 35 | BM33: 1 | BO33: 19 | BR33: 9 | BT33: 28 | BU33: 3 | BX33: 60 | BZ33: 43 | CB33: 103 | CE33: 6 | CH33: 149 | CK33: 120 | CN33: 269 | CP33: 7 | CS33: 1 | CU33: 8 | CW33: SUCCESS | DA33: =CN33*150 -> 40350
A34: 28
A35: 29
A36: 30
A37: 31
A38: 32
A39: 33
A40: 34
A41: 35
A42: 36
A43: 37
A44: 38
A45: 39
... A50: 44
B51: TOTAL | K51: 60 | M51: 2412 | O51: 2182 | Q51: 4594 | S51: 59 | U51: 2300 | X51: 2284 | AA51: 4584 | AC51: 55 | AE51: 1970 | AG51: 1987 | AI51: 3957 | AK51: 174 | AM51: 6682 | AO51: 6453 | AS51: 13135 | AV51: 56 | AX51: 2013 | AZ51: 1867 | BA51: 3880 | BC51: 53 | BD51: 1800 | BG51: 1576 | BI51: 3376 | BM51: 52 | BO51: 1242 | BR51: 1278 | BT51: 2520 | BU51: 161 | BX51: 5055 | BZ51: 4721 | CB51: 9776 | CE51: 335 | CH51: 11737 | CK51: 11174 | CN51: =SUM(CN7:CO33) -> 22911 | CP51: 247 | CS51: 277 | CU51: 524 | CW51: 27 | DA51: =SUM(DA7:DA29) -> 2610000
CH52: AMOUNT DUE FOR ZEO @ ₦20 per learner = | DA52: =CN51*20 -> 458220
A53: TOTAL RUNNING COST REQUIRED FOR YEWA SOUTH | DA53: =DA52+DA51 -> 3068220
CK54: =COUNTIF(CN7:CO29, "<1000") -> 14 | CL54: =COUNTIF(CN7:CO29, ">1000") -> 9
...

Sheet YEWA NORTH NEW
A1: MINISTRY OF EDUCATION, SCIENCE AND TECHNOLOGY
A2: DEPARTMENT OF SECONDARY EDUCATION
A4: SITUATION REPORT OF SECONDARY SCHOOLS
A5: S/N | B5: NAME OF SCHOOL
B7: PUBLIC JUNIOR SECONDARY SCHOOLS
A8: 1 | B8: Ajoda High School (Junior) Ayetoro
A9: 2 | B9: Alaye High School (Junior) Ayetoro
A10: 3 | B10: Ayetoro Community Grammar School (Junior) Ayetoro
A11: 4 | B11: Community High School (Junior) Ijoun
A12: 5 | B12: Comprehensive High School (Junior) Ayetoro
A13: 6 | B13: Ketu College (Junior) Igan - Alade
A14: 7 | B14: Oluaso High School (Junior) Imasayi
A15: 8 | B15: Orita Community High School (Junior) Oja Odan
A16: 9 | B16: Owode Ketu Commercial High School (Junior) Owode Ketu
A17: 10 | B17: Yewa Secondary School (Junior) Igbogila
B18: PUBLIC SENIOR SECONDARY SCHOOLS
A19: 11 | B19: Ajoda High School (Senior) Ayetoro
A20: 12 | B20: Alaye High School (Senior) Ayetoro
A21: 13 | B21: Ayetoro Community Grammar School (Senior) Ayetoro
A22: 14 | B22: Community High School (Senior) Ijoun
A23: 15 | B23: Comprehensive High School (Senior) Ayetoro
A24: 16 | B24: Ketu College (Senior) Igan - Alade
A25: 17 | B25: Oluaso High School (Senior) Imasayi
A26: 18 | B26: Orita Community High School (Senior) Oja Odan
A27: 19 | B27: Owode Ketu Commercial High School (Senior) Owode Ketu
A28: 20 | B28: Yewa Secondary School (Senior) Igbogila
B29: PUBLIC COMBINED SECONDARY SCHOOLS
A30: 21 | B30: Adokun High School, Igan Okoto
A31: 22 | B31: Area Community High School
A32: 23 | B32: Asakanran Grammar School, Ibese
A33: 24 | B33: Community High School, Ebute-Igbooro
A34: 25 | B34: Community High School, Agbon-Ojodu
A35: 26 | B35: Community Comprehensive High School, Eggua
A36: 27 | B36: Community High School Ohunbe
A37: 28 | B37: Eyinni Comp. High School Iboro
A38: 29 | B38: F.A.C.M(UNA) High School, Igbogila
A39: 30 | B39: Government Science and Technical College, Ayetoro
A40: 31 | B40: Community Grammar School, Igbokofi
A41: 32 | B41: Ketu Community High School, Ijale Ketu
... A44: 35 | B44: Sawonjo High School, Sawonjo
...

Sheet YEWA NORTH
A1: MINISTRY OF EDUCATION SCIENCE AND TECHNOLOGY
A2: DEPARTMENT OF SECONDARY RUNNING COST ANALYSIS BY ZONES
A3: RUNNING COST ANALYSIS
A4: YEWA NORTH
A5: ZONE: | E5: YEWA NORTH | AC5: NUMBER OF SECONDARY SCHOOLS AVAILABLE | AM5: 32 | AW5: DATA ENTRY STATUS: | BM5: YEWA NORTH
A6: S/N | B6: NAME OF SCHOOLS ( IN FULL AND UPPER CASE) | E6: L.G/LCDA | I6: WARD | J6: J S S 1 | R6: J S S 2 | AA6: J S S 3 | AI6: SUB TOTAL J S S 1 - J S S 3 | AS6: S S S 1 | BA6: S S S 2 | BI6: S S S 3 | BR6: SUB TOTAL S S S 1 - S S S 3 | CA6: TOTAL NUMBER OF LEARNERS | CM6: NUMBER OF TEACHERS | CV6: STATUS | CY6: RUNNING COST @ ₦30,000 FOR LEARNERS < 1000 PER MONTH FOR 3 MONTHS & @ ₦50,000 FOR LEARNERS > 1000 PER MONTH FOR 3 MONTHS
J7: ARM | L7: M | N7: F | P7: T | R7: ARM | T7: M | V7: F | Y7: T | AA7: ARM | AC7: M | AE7: F | AG7: T | AI7: ARM | AK7: M | AM7: F | AP7: T | AS7: ARM | AU7: M | AW7: F | AY7: T | BA7: ARM | BB7: M | BD7: F | BF7: T | BI7: ARM | BK7: M | BM7: F | BP7: T | BR7: ARM | BT7: M | BV7: F | BY7: T | CA7: ARM | CD7: M | CG7: F | CJ7: TOTAL | CM7: M | CP7: F | CS7: T
A8: 1 | B8: COMPREHENSIVE HIGH SCHOOL JUNIOR, AYETORO | E8: 1SOKAN | I8: AYE TOR O | J8: 5 | L8: 228 | N8: 271 | P8: 499 | R8: 5 | T8: 190 | V8: 177 | Y8: 367 | AA8: 4 | AC8: 154 | AE8: 148 | AG8: 302 | AI8: 14 | AK8: 572 | AM8: 596 | AP8: 1168 | AS8: 0 | AU8: 0 | AW8: 0 | AY8: 0 | BA8: 0 | BB8: 0 | BD8: 0 | BF8: 0 | BI8: 0 | BK8: 0 | BM8: 0 | BP8: 0 | BR8: 0 | BT8: 0 | BV8: 0 | BY8: 0 | CA8: 14 | CD8: 572 | CG8: 596 | CJ8: 1168 | CM8: 17 | CP8: 12 | CS8: 29 | CV8: SUCCESS | CY8: =IF(CJ8<1001,30000 * 3,50000*3) -> 150000
A9: 2 | B9: AYETORO COMMUNITY GRAMMAR SCHOOL JUNIOR, AYETORO | E9: ISOKAN | I9: AYE TOR O | J9: 2 | L9: 79 | N9: 58 | P9: 137 | R9: 2 | T9: 55 | V9: 39 | Y9: 94 | AA9: 2 | AC9: 35 | AE9: 43 | AG9: 78 | AI9: 6 | AK9: 169 | AM9: 140 | AP9: 309 | AS9: 0 | AU9: 0 | AW9: 0 | AY9: 0 | BA9: 0 | BB9: 0 | BD9: 0 | BF9: 0 | BI9: 0 | BK9: 0 | BM9: 0 | BP9: 0 | BR9: 0 | BT9: 0 | BV9: 0 | BY9: 0 | CA9: 6 | CD9: 169 | CG9: 140 | CJ9: 309 | CM9: 6 | CP9: 5 | CS9: 11 | CV9: SUCCESS | CY9: =IF(CJ9<1001,30000 * 3,50000*3) -> 90000
A10: 3 | B10: ALAYE HIGH SCHOOL JUNIOR, AYETORO | E10: ISOKAN | I10: AYE TOR O WAR D 2 | J10: 4 | L10: 160 | N10: 145 | P10: 305 | R10: 4 | T10: 186 | V10: 133 | Y10: 319 | AA10: 3 | AC10: 165 | AE10: 130 | AG10: 295 | AI10: 11 | AK10: 511 | AM10: 408 | AP10: 919 | AS10: 0 | AU10: 0 | AW10: 0 | AY10: 0 | BA10: 0 | BB10: 0 | BD10: 0 | BF10: 0 | BI10: 0 | BK10: 0 | BM10: 0 | BP10: 0 | BR10: 0 | BT10: 0 | BV10: 0 | BY10: 0 | CA10: 11 | CD10: 511 | CG10: 408 | CJ10: 919 | CM10: 10 | CP10: 5 | CS10: 15 | CV10: SUCCESS | CY10: =IF(CJ10<1001,30000 * 3,50000*3) -> 90000
A11: 4 | B11: AJODA HIGH SCHOOL JUNIOR, AYETORO | E11: ISOKAN | I11: AYE TOR O | J11: 4 | L11: 131 | N11: 143 | P11: 274 | R11: 4 | T11: 137 | V11: 139 | Y11: 276 | AA11: 4 | AC11: 126 | AE11: 128 | AG11: 254 | AI11: 12 | AK11: 394 | AM11: 410 | AP11: 804 | AS11: 0 | AU11: 0 | AW11: 0 | AY11: 0 | BA11: 0 | BB11: 0 | BD11: 0 | BF11: 0 | BI11: 0 | BK11: 0 | BM11: 0 | BP11: 0 | BR11: 0 | BT11: 0 | BV11: 0 | BY11: 0 | CA11: 12 | CD11: 394 | CG11: 410 | CJ11: 804 | CM11: 7 | CP11: 7 | CS11: 14 | CV11: SUCCESS | CY11: =IF(CJ11<1001,30000 * 3,50000*3) -> 90000
A12: 5 | B12: OWODE KETU COMMERCIAL HIGH SCHOOL JUNIOR, OWODE KETU | E12: KETU | I12: EGG UA | J12: 2 | L12: 51 | N12: 33 | P12: 84 | R12: 2 | T12: 40 | V12: 38 | Y12: 78 | AA12: 2 | AC12: 47 | AE12: 50 | AG12: 97 | AI12: 6 | AK12: 138 | AM12: 121 | AP12: 259 | AS12: 0 | AU12: 0 | AW12: 0 | AY12: 0 | BA12: 0 | BB12: 0 | BD12: 0 | BF12: 0 | BI12: 0 | BK12: 0 | BM12: 0 | BP12: 0 | BR12: 0 | BT12: 0 | BV12: 0 | BY12: 0 | CA12: 6 | CD12: 138 | CG12: 121 | CJ12: 259 | CM12: 3 | CP12: 1 | CS12: 4 | CV12: SUCCESS | CY12: =IF(CJ12<1001,30000 * 3,50000*3) -> 90000
A13: 6 | B13: OLUASO HIGH SCHOOL JUNIOR, OLUASO | E13: IJU | I13: IMAS AYI | J13: 2 | L13: 63 | N13: 67 | P13: 130 | R13: 2 | T13: 71 | V13: 55 | Y13: 126 | AA13: 2 | AC13: 94 | AE13: 80 | AG13: 174 | AI13: 6 | AK13: 228 | AM13: 202 | AP13: 430 | AS13: 0 | AU13: 0 | AW13: 0 | AY13: 0 | BA13: 0 | BB13: 0 | BD13: 0 | BF13: 0 | BI13: 0 | BK13: 0 | BM13: 0 | BP13: 0 | BR13: 0 | BT13: 0 | BV13: 0 | BY13: 0 | CA13: 6 | CD13: 228 | CG13: 202 | CJ13: 430 | CM13: 4 | CP13: 3 | CS13: 7 | CV13: SUCCESS | CY13: =IF(CJ13<1001,30000 * 3,50000*3) -> 90000
A14: 7 | B14: YEWA SECONDARY SCHOOL JUNIOR, IGBOGILA | E14: IJU | I14: IGBO GILA | J14: 4 | L14: 116 | N14: 112 | P14: 228 | R14: 4 | T14: 96 | V14: 91 | Y14: 187 | AA14: 3 | AC14: 65 | AE14: 75 | AG14: 140 | AI14: 11 | AK14: 277 | AM14: 278 | AP14: 555 | AS14: 0 | AU14: 0 | AW14: 0 | AY14: 0 | BA14: 0 | BB14: 0 | BD14: 0 | BF14: 0 | BI14: 0 | BK14: 0 | BM14: 0 | BP14: 0 | BR14: 0 | BT14: 0 | BV14: 0 | BY14: 0 | CA14: 11 | CD14: 277 | CG14: 278 | CJ14: 555 | CM14: 10 | CP14: 3 | CS14: 13 | CV14: SUCCESS | CY14: =IF(CJ14<1001,30000 * 3,50000*3) -> 90000
A15: 8 | B15: KETU COLLEGE JUNIOR, IGAN ALADE | E15: KETU | I15: EGG UA | J15: 2 | L15: 60 | N15: 66 | P15: 126 | R15: 2 | T15: 58 | V15: 65 | Y15: 123 | AA15: 2 | AC15: 54 | AE15: 52 | AG15: 106 | AI15: 6 | AK15: 172 | AM15: 183 | AP15: 355 | AS15: 0 | AU15: 0 | AW15: 0 | AY15: 0 | BA15: 0 | BB15: 0 | BD15: 0 | BF15: 0 | BI15: 0 | BK15: 0 | BM15: 0 | BP15: 0 | BR15: 0 | BT15: 0 | BV15: 0 | BY15: 0 | CA15: 6 | CD15: 172 | CG15: 183 | CJ15: 355 | CM15: 4 | CP15: 1 | CS15: 5 | CV15: SUCCESS | CY15: =IF(CJ15<1001,30000 * 3,50000*3) -> 90000
A16: 9 | B16: COMMUNITY HIGH SCHOOL JUNIOR, IJOUN | E16: KETU | I16: IJOU N | J16: 3 | L16: 102 | N16: 101 | P16: 203 | R16: 3 | T16: 110 | V16: 95 | Y16: 205 | AA16: 3 | AC16: 72 | AE16: 67 | AG16: 139 | AI16: 9 | AK16: 284 | AM16: 263 | AP16: 547 | AS16: 0 | AU16: 0 | AW16: 0 | AY16: 0 | BA16: 0 | BB16: 0 | BD16: 0 | BF16: 0 | BI16: 0 | BK16: 0 | BM16: 0 | BP16: 0 | BR16: 0 | BT16: 0 | BV16: 0 | BY16: 0 | CA16: 9 | CD16: 284 | CG16: 263 | CJ16: 547 | CM16: 6 | CP16: 0 | CS16: 6 | CV16: SUCCESS | CY16: =IF(CJ16<1001,30000 * 3,50000*3) -> 90000
A17: 10 | B17: ORITA COMMUNITY HIGH SCHOOL JUNIOR, OJA ODAN | E17: KETU | I17: EBU TE | J17: 4 | L17: 210 | N17: 171 | P17: 381 | R17: 4 | T17: 225 | V17: 165 | Y17: 390 | AA17: 4 | AC17: 158 | AE17: 140 | AG17: 298 | AI17: 12 | AK17: 593 | AM17: 476 | AP17: 1069 | AS17: 0 | AU17: 0 | AW17: 0 | AY17: 0 | BA17: 0 | BB17: 0 | BD17: 0 | BF17: 0 | BI17: 0 | BK17: 0 | BM17: 0 | BP17: 0 | BR17: 0 | BT17: 0 | BV17: 0 | BY17: 0 | CA17: 12 | CD17: 593 | CG17: 476 | CJ17: 1069 | CM17: 9 | CP17: 5 | CS17: 14 | CV17: SUCCESS | CY17: =IF(CJ17<1001,30000 * 3,50000*3) -> 150000
A18: 11 | B18: GOVERNMENT SCIENCE AND TECHNICAL COLLEGE JUNIOR, AYETORO | E18: ISOKAN | I18: AYE TOR O | J18: 3 | L18: 83 | N18: 61 | P18: 144 | R18: 3 | T18: 77 | V18: 66 | Y18: 143 | AA18: 2 | AC18: 91 | AE18: 59 | AG18: 150 | AI18: 8 | AK18: 251 | AM18: 186 | AP18: 437 | AS18: 0 | AU18: 0 | AW18: 0 | AY18: 0 | BA18: 0 | BB18: 0 | BD18: 0 | BF18: 0 | BI18: 0 | BK18: 0 | BM18: 0 | BP18: 0 | BR18: 0 | BT18: 0 | BV18: 0 | BY18: 0 | CA18: 8 | CD18: 251 | CG18: 186 | CJ18: 437 | CM18: 15 | CP18: 5 | CS18: 20 | CV18: SUCCESS | CY18: =IF(CJ18<1001,30000 * 3,50000*3) -> 90000
A19: 12 | B19: COMPREHENSIVE HIGH SCHOOL SENIOR, AYETORO | E19: IDOFOI | I19: AYE TOR O | J19: 0 | L19: 0 | N19: 0 | P19: 0 | R19: 0 | T19: 0 | V19: 0 | Y19: 0 | AA19: 0 | AC19: 0 | AE19: 0 | AG19: 0 | AI19: 0 | AK19: 0 | AM19: 0 | AP19: 0 | AS19: 9 | AU19: 278 | AW19: 272 | AY19: 550 | BA19: 9 | BB19: 170 | BD19: 166 | BF19: 336 | BI19: 9 | BK19: 152 | BM19: 158 | BP19: 310 | BR19: 27 | BT19: 600 | BV19: 596 | BY19: 1196 | CA19: 27 | CD19: 600 | CG19: 596 | CJ19: 1196 | CM19: 14 | CP19: 13 | CS19: 27 | CV19: SUCCESS | CY19: =IF(CJ19<1001,30000 * 3,50000*3) -> 150000
... A39: 32 | B39: ADOKUN HIGH SCHOOL. IGAN OKOTO | E39: IJU | I39: SUN WA | J39: 1 | L39: 32 | N39: 34 | P39: 66 | R39: 1 | T39: 23 | V39: 21 | Y39: 44 | AA39: 1 | AC39: 26 | AE39: 20 | AG39: 46 | AI39: 3 | AK39: 81 | AM39: 75 | AP39: 156 | AS39: 1 | AU39: 20 | AW39: 21 | AY39: 41 | BA39: 1 | BB39: 29 | BD39: 18 | BF39: 47 | BI39: 1 | BK39: 20 | BM39: 15 | BP39: 35 | BR39: 3 | BT39: 69 | BV39: 54 | BY39: 123 | CA39: 6 | CD39: 150 | CG39: 129 | CJ39: 279 | CM39: 5 | CP39: 6 | CS39: 11 | CV39: SUCCESS | CY39: =IF(CJ39<1001,30000 * 3,50000*3) -> 90000
B40: TOTAL | J40: 52 | L40: 1851 | N40: 1707 | P40: 3558 | R40: 52 | T40: 1761 | V40: 1487 | Y40: 3248 | AA40: 47 | AC40: 1537 | AE40: 1416 | AG40: 2953 | AI40: 151 | AK40: 5149 | AM40: 4610 | AP40: 9759 | AS40: 48 | AU40: 1425 | AW40: 1190 | AY40: 2615 | BA40: 48 | BB40: 1186 | BD40: 1024 | BF40: 2210 | BI40: 45 | BK40: 873 | BM40: 762 | BP40: 1635 | BR40: 141 | BT40: 3484 | BV40: 2976 | BY40: 6460 | CA40: 292 | CD40: 8633 | CG40: 7586 | CJ40: 16219 | CM40: 274 | CP40: 115 | CS40: 389 | CV40: 32 | CY40: =SUM(CY8:CY39) -> 3120000
E41: 32 | I41: AMOUNT DUE FOR ZEO @ ₦20 per candidate = | CM41: 15 | CP41: 5 | CS41: 20 | CY41: =CJ40*20 -> 324380
A42: TOTAL RUNNING COST REQUIRED FOR YEWA NORTH | CM42: 259 | CP42: 110 | CS42: 369 | CV42: LESS GSTC TEACHERS | CY42: =CY40+CY41 -> 3444380
CD43: =COUNTIF(CJ8:CL39, "<1000") -> 28 | CE43: =COUNTIF(CJ8:CL39, ">1000") -> 4
B44: =COUNTA(B8:D39)-COUNTIF(B8:D39,"GOVERNMENT SCIENCE") -> 32 | C44: =COUNTIF(B8:D39,"GOVERNMENT SCIENCE") -> 0

Sheet Remo north new 
A1: MINISTRY OF EDUCATION SCIENCE AND TECHNOLOGY
A2: DEPARTMENT OF SECONDARY RUNNING COST ANALYSIS BY ZONES
A3: REMO NORTH
A4: S/N | B4: NAME OF SCHOOLS
A6: 1 | B6: GOVERNMENT SCIENCE AND TECHNICAL COLLEGE, ILARA REMO
A7: 2 | B7: ODE REMO HIGH SCHOOL (JUNIOR), ODE REMO
A8: 3 | B8: ODE REMO HIGH SCHOOL (SENIOR), ODE REMO
A9: 4 | B9: ISARA SECONDARY SCHOOL, ISARA REMO
A10: 5 | B10: IYANKAN HIGH SCHOOL, ISARA REMO
A11: 6 | B11: ORILE OKO COMMUNITY HIGH SCHOOL, ISAN
A12: 7 | B12: SAAPADE GRAMMAR SCHOOL, SAAPADE
A13: 8 | B13: IPARA COMMUNITY HIGH SCHOOL, IPARA REMO
A14: 9 | B14: ILARA/AKAKA COMMUNITY GRAMMAR SCHOOL, ILARA
B17: =COUNTA(A6:A14) -> 9

Sheet Remo North
A1: MINISTRY OF EDUCATION SCIENCE AND TECHNOLOGY
A2: DEPARTMENT OF SECONDARY RUNNING COST ANALYSIS BY ZONES
A3: RUNNING COST ANALYSIS
A4: REMO NORTH
A5: S/N | B5: NAME OF SCHOOLS ( IN FULL AND UPPER CASE) | G5: L.G/LCDA | J5: WARD | L5: J S S 1 | T5: J S S 2 | AC5: J S S 3 | AK5: SUB TOTAL J S S 1 - J S S 3 | AV5: S S S 1 | BB5: S S S 2 | BK5: S S S 3 | BT5: SUB TOTAL S S S 1 - S S S 3 | CD5: GRAND TOTAL | CP5: NUMBER OF TEACHERS | CX5: STATUS | DB5: RUNNING COST @ ₦30,000 FOR LEARNERS < 1000 PER MONTH FOR 3 MONTHS & @ ₦50,000 FOR LEARNERS > 1000 PER MONTH FOR 3 MONTHS
L6: ARM | N6: M | P6: F | R6: T | T6: ARM | V6: M | Y6: F | AA6: T | AC6: ARM | AE6: M | AG6: F | AI6: T | AK6: ARM | AM6: M | AO6: F | AS6: T | AV6: ARM | AW6: M | AY6: F | BA6: T | BB6: ARM | BD6: M | BF6: F | BI6: T | BK6: ARM | BM6: M | BP6: F | BR6: T | BT6: ARM | BV6: M | BY6: F | CA6: T | CD6: ARM | CG6: M | CJ6: F | CM6: T | CP6: M | CS6: F | CV6: T
A7: 1 | B7: ODE REMO HIGH SCHOOL (JUNIOR), ODE | G7: REMO NORTH EAST | J7: 9 | L7: 3 | N7: 121 | P7: 129 | R7: 250 | T7: 4 | V7: 123 | Y7: 129 | AA7: 252 | AC7: 3 | AE7: 117 | AG7: 110 | AI7: 227 | AK7: 10 | AM7: 361 | AO7: 368 | AS7: 729 | AV7: 0 | AW7: 0 | AY7: 0 | BA7: 0 | BB7: 0 | BD7: 0 | BF7: 0 | BI7: 0 | BK7: 0 | BM7: 0 | BP7: 0 | BR7: 0 | BT7: 0 | BV7: 0 | BY7: 0 | CA7: 0 | CD7: 10 | CG7: 361 | CJ7: 368 | CM7: 729 | CP7: 5 | CS7: 8 | CV7: 13 | CX7: SUCCESS | DB7: =IF(CL39<1001,30000 * 3,50000*3) -> 90000
A8: 2 | B8: ODE REMO HIGH SCHOOL (SENIOR), ODE | G8: REMO NORTH EAST | J8: 9 | L8: 0 | N8: 0 | P8: 0 | R8: 0 | T8: 0 | V8: 0 | Y8: 0 | AA8: 0 | AC8: 0 | AE8: 0 | AG8: 0 | AI8: 0 | AK8: 0 | AM8: 0 | AO8: 0 | AS8: 0 | AV8: 3 | AW8: 90 | AY8: 76 | BA8: 166 | BB8: 3 | BD8: 65 | BF8: 66 | BI8: 131 | BK8: 3 | BM8: 56 | BP8: 38 | BR8: 94 | BT8: 9 | BV8: 211 | BY8: 180 | CA8: 391 | CD8: 9 | CG8: 211 | CJ8: 180 | CM8: 391 | CP8: 8 | CS8: 9 | CV8: 17 | CX8: SUCCESS | DB8: =IF(CL40<1001,30000 * 3,50000*3) -> 90000
A9: 3 | B9: IPARA COMMUNITY HIGH SCHOOL, IPARA | G9: REMO NORTH EAST | J9: 7 | L9: 2 | N9: 72 | P9: 55 | R9: 127 | T9: 2 | V9: 40 | Y9: 45 | AA9: 85 | AC9: 2 | AE9: 46 | AG9: 41 | AI9: 87 | AK9: 6 | AM9: 158 | AO9: 141 | AS9: 299 | AV9: 3 | AW9: 29 | AY9: 31 | BA9: 60 | BB9: 3 | BD9: 41 | BF9: 40 | BI9: 81 | BK9: 3 | BM9: 34 | BP9: 32 | BR9: 66 | BT9: 9 | BV9: 104 | BY9: 103 | CA9: 207 | CD9: 15 | CG9: 262 | CJ9: 244 | CM9: 506 | CP9: 11 | CS9: 5 | CV9: 16 | CX9: SUCCESS | DB9: =IF(CL41<1001,30000 * 3,50000*3) -> 90000
A10: 4 | B10: ISARA SECONDARY SCHOOL, ISARA | G10: REMO NORTH | J10: 3 | L10: 3 | N10: 127 | P10: 112 | R10: 239 | T10: 3 | V10: 131 | Y10: 76 | AA10: 207 | AC10: 3 | AE10: 69 | AG10: 66 | AI10: 135 | AK10: 9 | AM10: 327 | AO10: 254 | AS10: 581 | AV10: 3 | AW10: 76 | AY10: 55 | BA10: 131 | BB10: 3 | BD10: 54 | BF10: 41 | BI10: 95 | BK10: 3 | BM10: 25 | BP10: 29 | BR10: 54 | BT10: 9 | BV10: 155 | BY10: 125 | CA10: 280 | CD10: 18 | CG10: 482 | CJ10: 379 | CM10: 861 | CP10: 9 | CS10: 10 | CV10: 19 | CX10: SUCCESS | DB10: =IF(CL42<1001,30000 * 3,50000*3) -> 90000
A11: 5 | B11: IYANKAN COMMUNITY HIGH SCHOOL, IYANKAN | G11: REMO NORTH | J11: 3 | L11: 1 | N11: 7 | P11: 12 | R11: 19 | T11: 1 | V11: 7 | Y11: 6 | AA11: 13 | AC11: 1 | AE11: 11 | AG11: 6 | AI11: 17 | AK11: 3 | AM11: 25 | AO11: 24 | AS11: 49 | AV11: 1 | AW11: 6 | AY11: 7 | BA11: 13 | BB11: 1 | BD11: 6 | BF11: 4 | BI11: 10 | BK11: 1 | BM11: 3 | BP11: 3 | BR11: 6 | BT11: 3 | BV11: 15 | BY11: 14 | CA11: 29 | CD11: 6 | CG11: 40 | CJ11: 38 | CM11: 78 | CP11: 3 | CS11: 7 | CV11: 10 | CX11: SUCCESS | DB11: =IF(CL43<1001,30000 * 3,50000*3) -> 90000
A12: 6 | B12: ORILE OKO COMMUNITY HIGH SCHOOL, ISAN | G12: REMO NORTH | J12: 8 | L12: 1 | N12: 40 | P12: 40 | R12: 80 | T12: 1 | V12: 25 | Y12: 27 | AA12: 52 | AC12: 1 | AE12: 27 | AG12: 25 | AI12: 52 | AK12: 3 | AM12: 92 | AO12: 92 | AS12: 184 | AV12: 1 | AW12: 17 | AY12: 16 | BA12: 33 | BB12: 1 | BD12: 12 | BF12: 13 | BI12: 25 | BK12: 1 | BM12: 12 | BP12: 18 | BR12: 30 | BT12: 3 | BV12: 41 | BY12: 47 | CA12: 88 | CD12: 6 | CG12: 133 | CJ12: 139 | CM12: 272 | CP12: 9 | CS12: 3 | CV12: 12 | CX12: SUCCESS | DB12: =IF(CL44<1001,30000 * 3,50000*3) -> 90000
A13: 7 | B13: SAAPADE GRAMMAR SCHOOL, SAAPADE | G13: REMO NORTH | J13: 2 | L13: 2 | N13: 48 | P13: 52 | R13: 100 | T13: 2 | V13: 47 | Y13: 66 | AA13: 113 | AC13: 2 | AE13: 50 | AG13: 60 | AI13: 110 | AK13: 6 | AM13: 145 | AO13: 178 | AS13: 323 | AV13: 2 | AW13: 50 | AY13: 62 | BA13: 112 | BB13: 2 | BD13: 30 | BF13: 39 | BI13: 69 | BK13: 2 | BM13: 28 | BP13: 23 | BR13: 51 | BT13: 6 | BV13: 108 | BY13: 124 | CA13: 232 | CD13: 12 | CG13: 253 | CJ13: 302 | CM13: 555 | CP13: 15 | CS13: 4 | CV13: 19 | CX13: SUCCESS | DB13: =IF(CL45<1001,30000 * 3,50000*3) -> 90000
A14: 8 | B14: ILARA/AKAKA COMMUNITY GRAMMAR SCHOOL, ILARA/AKAKA | G14: REMO NORTH EAST | J14: 5 | L14: 1 | N14: 25 | P14: 19 | R14: 44 | T14: 1 | V14: 7 | Y14: 3 | AA14: 10 | AC14: 1 | AE14: 5 | AG14: 8 | AI14: 13 | AK14: 3 | AM14: 37 | AO14: 30 | AS14: 67 | AV14: 1 | AW14: 3 | AY14: 3 | BA14: 6 | BB14: 1 | BD14: 6 | BF14: 4 | BI14: 10 | BK14: 1 | BM14: 9 | BP14: 1 | BR14: 10 | BT14: 3 | BV14: 18 | BY14: 8 | CA14: 26 | CD14: 6 | CG14: 55 | CJ14: 38 | CM14: 93 | CP14: 8 | CS14: 6 | CV14: 14 | CX14: SUCCESS | DB14: =IF(CL46<1001,30000 * 3,50000*3) -> 90000
A15: 9 | B15: GOVERNMENT SCIENCE AND TECHNICAL COLLEGE, ILARA | G15: REMO NORTH EAST | J15: 5 | L15: 1 | N15: 3 | P15: 2 | R15: 5 | T15: 1 | V15: 6 | Y15: 7 | AA15: 13 | AC15: 1 | AE15: 5 | AG15: 5 | AI15: 10 | AK15: 3 | AM15: 14 | AO15: 14 | AS15: 28 | AV15: 0 | AW15: 0 | AY15: 0 | BA15: 0 | BB15: 0 | BD15: 0 | BF15: 0 | BI15: 0 | BK15: 0 | BM15: 0 | BP15: 0 | BR15: 0 | BT15: 0 | BV15: 0 | BY15: 0 | CA15: 0 | CD15: 3 | CG15: 14 | CJ15: 14 | CM15: 28 | CP15: 12 | CS15: 11 | CV15: 23 | CX15: SUCCESS | DB15: =IF(CL47<1001,30000 * 3,50000*3) -> 90000
B16: TOTAL | L16: 14 | N16: 443 | P16: 421 | R16: 864 | T16: 15 | V16: 386 | Y16: 359 | AA16: 745 | AC16: 14 | AE16: 330 | AG16: 321 | AI16: 651 | AK16: 43 | AM16: 1159 | AO16: 1101 | AS16: 2260 | AV16: 14 | AW16: 271 | AY16: 250 | BA16: 521 | BB16: 14 | BD16: 214 | BF16: 207 | BI16: 421 | BK16: 14 | BM16: 167 | BP16: 144 | BR16: 311 | BT16: 42 | BV16: 652 | BY16: 601 | CA16: 1253 | CD16: 85 | CG16: 1811 | CJ16: 1702 | CM16: 3513 | CP16: 80 | CS16: 63 | CV16: 143 | CX16: 9 | DB16: =SUM(DB7:DB15) -> 810000
G17: 9 | J17: AMOUNT DUE FOR ZEO @ ₦20 per candidate = | CP17: 12 | CS17: 11 | CV17: 23 | DB17: =CM16*20 -> 70260
CD18: TOTAL RUNNING COST REQUIRED FOR REMO NORTH | CP18: 68 | CS18: 52 | CV18: 120 | CX18: LESS GSTC TEACHERS | DB18: =DB16+DB17 -> 880260
CD19: =COUNTIF(CM7:CO15, "<1000") -> 9 | CE19: =COUNTIF(CM7:CO15, ">1000") -> 0
B20: =COUNTA(B7:F15)-COUNTIF(B7:F15,"GOVERNMENT SCIENCE") -> 9 | C20: =COUNTIF(B7:D38,"GOVERNMENT SCIENCE") -> 0

Sheet Sagamu New
A1: MINISTRY OF EDUCATION SCIENCE AND TECHNOLOGY
A2: DEPARTMENT OF SECONDARY RUNNING COST ANALYSIS BY ZONES
A3: SAGAMU
A4: S/NO | B4: NAME OF SCHOOL
B5: JUNIOR SCHOOL
A6: 1 | B6: BATORO COMMUNITY HIGH SCHOOL, SAGAMU
A7: 2 | B7: MAKUN HIGH SCHOOL, SAGAMU
A8: 3 | B8: METHODIST COMPREHENSIVE COLLEGE, SAGAMU
A9: 4 | B9: MUSLIM HIGH SCHOOL, SAGAMU
A10: 5 | B10: OGIJO COMMUNITY HIGH SCHOOL, OGIJO
A11: 6 | B11: REMO DIVISIONAL HIGH SCHOOL, SAGAMU
A12: 7 | B12: REMO SECONDARY SCHOOL, SAGAMU
A13: 8 | B13: SAGAMU HIGH SCHOOL, SAGAMU
A14: 9 | B14: SONYINDO COMMUNITY HIGH SCHOOL, SAGAMU
B15: SENIOR SCHOOL
A16: 10 | B16: BATORO COMMUNITY HIGH SCHOOL, SAGAMU
A17: 11 | B17: MAKUN HIGH SCHOOL, SAGAMU
A18: 12 | B18: METHODIST COMPREHENSIVE COLLEGE, SAGAMU
A19: 13 | B19: MUSLIM HIGH SCHOOL, SAGAMU
A20: 14 | B20: OGIJO COMMUNITY HIGH SCHOOL, OGIJO
A21: 15 | B21: REMO DIVISIONAL HIGH SCHOOL, SAGAMU
A22: 16 | B22: REMO SECONDARY SCHOOL, SAGAMU
A23: 17 | B23: SAGAMU HIGH SCHOOL, SAGAMU
A24: 18 | B24: SONYINDO COMMUNITY HIGH SCHOOL, SAGAMU
B25: COMBINED SCHOOL
A26: 19 | B26: AGBELE COMMUNITY HIGH SCHOOL, SAGAMU
A27: 20 | B27: COMMUNITY GRAMMAR SCHOOL, ODE-LEMO
A28: 21 | B28: DANIEL COMPREHENSIVE HIGH SCHOOL, SAGAMU
A29: 22 | B29: IJAGBA COMMUNITY HIGH SCHOOL, SOTUBO
A30: 23 | B30: MULERUWA COMMUNITY HIGH SCHOOL, GBAGA
